{
 "cells": [
  {
   "cell_type": "code",
   "execution_count": 7,
   "metadata": {},
   "outputs": [
    {
     "name": "stdout",
     "output_type": "stream",
     "text": [
      "35868\n",
      "8150\n"
     ]
    }
   ],
   "source": [
    "import tensorflow as tf\n",
    "from tensorflow import keras\n",
    "from scipy.stats import uniform\n",
    "from keras.models import Sequential\n",
    "from keras.layers import Embedding, Dropout, LSTM, Dense\n",
    "from sklearn.model_selection import train_test_split\n",
    "from keras.preprocessing.sequence import pad_sequences\n",
    "from sklearn.preprocessing import LabelEncoder\n",
    "from scikeras.wrappers import KerasClassifier\n",
    "from sklearn.model_selection import  RandomizedSearchCV\n",
    "from collections import Counter\n",
    "import numpy as np\n",
    "import pandas as pd\n",
    "from keras.preprocessing.text import Tokenizer\n",
    "\n",
    "# define the model\n",
    "def create_lstm_model(units, vocab_length, embedding_matrix, max_len, dropout):\n",
    "    lstm_model = Sequential()\n",
    "    embedding_layer = Embedding(vocab_length, 200, weights=[embedding_matrix], input_length=max_len, trainable=False)\n",
    "    lstm_model.add(embedding_layer)\n",
    "    lstm_model.add(Dropout(dropout))\n",
    "    lstm_model.add(LSTM(units))\n",
    "    lstm_model.add(Dense(5, activation='softmax'))\n",
    "    lstm_model.compile(optimizer='adam', loss='sparse_categorical_crossentropy', metrics=['acc'])\n",
    "    return lstm_model\n",
    "\n",
    "\n",
    "# fix random seed for reproducibility\n",
    "#tf.random.set_seed(7)\n",
    "\n",
    "df = pd.read_csv('../../data/normalized_tweets.csv')\n",
    "df = df[df['cyberbullying_type'] != 'other_cyberbullying']\n",
    "# Reset index after filtering out the class\n",
    "df.reset_index(drop=True, inplace=True)\n",
    "#df[\"cyberbullying_type\"].value_counts()\n",
    "\n",
    "### try different length based on tweet lentgh\n",
    "#df['text_len'] = [len(text.split()) for text in df.tweet_text]\n",
    "#max_len = np.max(df['text_len'])\n",
    "max_len = 25\n",
    "\n",
    "X, y = df[\"tweet_text\"], df[\"cyberbullying_type\"]\n",
    "\n",
    "# Initialize LabelEncoder\n",
    "label_encoder = LabelEncoder()\n",
    "\n",
    "# Fit and transform label encoder on the target variable\n",
    "y = label_encoder.fit_transform(y)\n",
    "\n",
    "x_train, x_test, y_train, y_test = train_test_split(X, y, test_size=0.2)\n",
    "#Each word in input used as a key, while a unique index is used as the value of the key \n",
    "word_tokenizer = Tokenizer()\n",
    "word_tokenizer.fit_on_texts(x_train)\n",
    "\n",
    "X_train = word_tokenizer.texts_to_sequences(x_train)\n",
    "X_test = word_tokenizer.texts_to_sequences(x_test)\n",
    "\n",
    "vocab_length = len(word_tokenizer.word_index) + 1\n",
    "\n",
    "print(vocab_length)\n",
    "\n",
    "####\n",
    "\n",
    "X_train = pad_sequences(X_train, padding = 'pre', maxlen = max_len)\n",
    "X_test = pad_sequences(X_test, padding = 'pre', maxlen = max_len)\n",
    "\n",
    "# Load GloVe word embeddings and create a dictionary that willl contain words as keys, and their corresponging embedding list as values. \n",
    "from numpy import asarray\n",
    "from numpy import zeros\n",
    "\n",
    "embeddings_dictionary = dict()\n",
    "glove_file = open('../../glove_embeddings/glove.twitter.27B.200d.txt', encoding=\"utf8\")\n",
    "\n",
    "for line in glove_file:\n",
    "    records = line.split()\n",
    "    word = records[0]\n",
    "    vector_dimensions = asarray(records[1:], dtype='float32')\n",
    "    embeddings_dictionary [word] = vector_dimensions\n",
    "glove_file.close()\n",
    "\n",
    "embedding_matrix = zeros((vocab_length, 200)) ## change if the dimention of embedding changes above\n",
    "i = 0\n",
    "for word, index in word_tokenizer.word_index.items():\n",
    "    embedding_vector = embeddings_dictionary.get(word)\n",
    "    if embedding_vector is not None:\n",
    "        embedding_matrix[index] = embedding_vector\n",
    "    else:\n",
    "        i = i + 1\n",
    "print(i)"
   ]
  },
  {
   "cell_type": "code",
   "execution_count": 8,
   "metadata": {},
   "outputs": [
    {
     "data": {
      "text/plain": [
       "array([   0,    0,    0,    0,    0,    0,    0,    0,    0,    0,    0,\n",
       "          0,    0,    0,    0,    0,    0,    0,    0,    0,    0,    0,\n",
       "         39, 4017, 1727], dtype=int32)"
      ]
     },
     "execution_count": 8,
     "metadata": {},
     "output_type": "execute_result"
    }
   ],
   "source": [
    "X_train[1]"
   ]
  },
  {
   "cell_type": "code",
   "execution_count": 9,
   "metadata": {},
   "outputs": [
    {
     "name": "stdout",
     "output_type": "stream",
     "text": [
      "Epoch 1/10\n",
      "Epoch 1/10\n",
      "Epoch 1/10\n",
      "Epoch 1/10\n",
      "Epoch 1/10\n",
      "Epoch 1/10\n",
      "Epoch 1/10\n",
      "Epoch 1/10\n",
      "Epoch 1/10\n",
      "Epoch 1/10\n",
      "Epoch 1/5\n",
      "154/154 [==============================] - 3s 16ms/step - loss: 0.6888 - acc: 0.7637 - val_loss: 0.3518 - val_acc: 0.8803\n",
      "Epoch 2/5\n",
      "154/154 [==============================] - 2s 15ms/step - loss: 0.3153 - acc: 0.8914 - val_loss: 0.2957 - val_acc: 0.8974\n",
      "Epoch 3/5\n",
      "154/154 [==============================] - 2s 15ms/step - loss: 0.2667 - acc: 0.9074 - val_loss: 0.2728 - val_acc: 0.9056\n",
      "Epoch 4/5\n",
      "154/154 [==============================] - 2s 15ms/step - loss: 0.2400 - acc: 0.9175 - val_loss: 0.2514 - val_acc: 0.9137\n",
      "Epoch 5/5\n",
      "154/154 [==============================] - 2s 15ms/step - loss: 0.2272 - acc: 0.9203 - val_loss: 0.2422 - val_acc: 0.9178\n",
      "48/48 [==============================] - 0s 5ms/step\n",
      "Epoch 1/5\n",
      "154/154 [==============================] - 3s 16ms/step - loss: 0.7269 - acc: 0.7483 - val_loss: 0.3479 - val_acc: 0.8799\n",
      "Epoch 2/5\n",
      "154/154 [==============================] - 2s 16ms/step - loss: 0.3232 - acc: 0.8912 - val_loss: 0.2897 - val_acc: 0.8980\n",
      "Epoch 3/5\n",
      "154/154 [==============================] - 2s 16ms/step - loss: 0.2690 - acc: 0.9068 - val_loss: 0.2614 - val_acc: 0.9050\n",
      "Epoch 4/5\n",
      "154/154 [==============================] - 2s 16ms/step - loss: 0.2426 - acc: 0.9151 - val_loss: 0.2543 - val_acc: 0.9121\n",
      "Epoch 5/5\n",
      "154/154 [==============================] - 2s 16ms/step - loss: 0.2244 - acc: 0.9231 - val_loss: 0.2369 - val_acc: 0.9166\n",
      "48/48 [==============================] - 0s 6ms/step\n",
      "Epoch 1/5\n",
      "154/154 [==============================] - 3s 17ms/step - loss: 0.7328 - acc: 0.7403 - val_loss: 0.3477 - val_acc: 0.8830\n",
      "Epoch 2/5\n",
      "154/154 [==============================] - 3s 16ms/step - loss: 0.3162 - acc: 0.8915 - val_loss: 0.2847 - val_acc: 0.8995\n",
      "Epoch 3/5\n",
      "154/154 [==============================] - 3s 16ms/step - loss: 0.2697 - acc: 0.9061 - val_loss: 0.2690 - val_acc: 0.9054\n",
      "Epoch 4/5\n",
      "154/154 [==============================] - 3s 16ms/step - loss: 0.2449 - acc: 0.9155 - val_loss: 0.2481 - val_acc: 0.9096\n",
      "Epoch 5/5\n",
      "154/154 [==============================] - 3s 17ms/step - loss: 0.2312 - acc: 0.9179 - val_loss: 0.2436 - val_acc: 0.9147\n",
      "48/48 [==============================] - 0s 6ms/step\n",
      "Epoch 1/5\n",
      "154/154 [==============================] - 4s 17ms/step - loss: 0.7189 - acc: 0.7488 - val_loss: 0.3525 - val_acc: 0.8838\n",
      "Epoch 2/5\n",
      "154/154 [==============================] - 3s 16ms/step - loss: 0.3168 - acc: 0.8934 - val_loss: 0.2935 - val_acc: 0.8980\n",
      "Epoch 3/5\n",
      "154/154 [==============================] - 3s 16ms/step - loss: 0.2688 - acc: 0.9070 - val_loss: 0.2606 - val_acc: 0.9052\n",
      "Epoch 4/5\n",
      "154/154 [==============================] - 2s 16ms/step - loss: 0.2470 - acc: 0.9146 - val_loss: 0.2493 - val_acc: 0.9101\n",
      "Epoch 5/5\n",
      "154/154 [==============================] - 3s 16ms/step - loss: 0.2250 - acc: 0.9214 - val_loss: 0.2375 - val_acc: 0.9139\n",
      "48/48 [==============================] - 0s 6ms/step\n",
      "Epoch 1/5\n",
      "154/154 [==============================] - 3s 18ms/step - loss: 0.7078 - acc: 0.7559 - val_loss: 0.3420 - val_acc: 0.8844\n",
      "Epoch 2/5\n",
      "154/154 [==============================] - 3s 17ms/step - loss: 0.3226 - acc: 0.8901 - val_loss: 0.2780 - val_acc: 0.9005\n",
      "Epoch 3/5\n",
      "154/154 [==============================] - 3s 16ms/step - loss: 0.2714 - acc: 0.9064 - val_loss: 0.2553 - val_acc: 0.9107\n",
      "Epoch 4/5\n",
      "154/154 [==============================] - 3s 17ms/step - loss: 0.2468 - acc: 0.9151 - val_loss: 0.2459 - val_acc: 0.9125\n",
      "Epoch 5/5\n",
      "154/154 [==============================] - 3s 17ms/step - loss: 0.2286 - acc: 0.9202 - val_loss: 0.2289 - val_acc: 0.9182\n",
      "48/48 [==============================] - 0s 6ms/step\n",
      "Epoch 1/10\n",
      "Epoch 1/10\n",
      "Epoch 1/10\n",
      "Epoch 1/10\n",
      "Epoch 1/10\n",
      "Epoch 1/10\n",
      "77/77 [==============================] - 11s 128ms/step - loss: 0.5224 - acc: 0.8166 - val_loss: 0.3111 - val_acc: 0.8891\n",
      "Epoch 2/10\n",
      "77/77 [==============================] - 10s 129ms/step - loss: 0.2871 - acc: 0.8964 - val_loss: 0.2641 - val_acc: 0.9013\n",
      "Epoch 3/10\n",
      "77/77 [==============================] - 10s 132ms/step - loss: 0.2485 - acc: 0.9132 - val_loss: 0.2503 - val_acc: 0.9076\n",
      "Epoch 4/10\n",
      "77/77 [==============================] - 10s 133ms/step - loss: 0.2277 - acc: 0.9197 - val_loss: 0.2382 - val_acc: 0.9135\n",
      "Epoch 5/10\n",
      "77/77 [==============================] - 10s 132ms/step - loss: 0.2016 - acc: 0.9276 - val_loss: 0.2306 - val_acc: 0.9178\n",
      "Epoch 6/10\n",
      "77/77 [==============================] - 10s 135ms/step - loss: 0.1863 - acc: 0.9337 - val_loss: 0.2193 - val_acc: 0.9214\n",
      "Epoch 7/10\n",
      "77/77 [==============================] - 10s 133ms/step - loss: 0.1687 - acc: 0.9388 - val_loss: 0.2233 - val_acc: 0.9190\n",
      "Epoch 8/10\n",
      "77/77 [==============================] - 10s 135ms/step - loss: 0.1595 - acc: 0.9415 - val_loss: 0.2105 - val_acc: 0.9245\n",
      "Epoch 9/10\n",
      "77/77 [==============================] - 10s 135ms/step - loss: 0.1443 - acc: 0.9480 - val_loss: 0.2140 - val_acc: 0.9243\n",
      "Epoch 10/10\n",
      "77/77 [==============================] - 11s 137ms/step - loss: 0.1425 - acc: 0.9468 - val_loss: 0.2218 - val_acc: 0.9176\n",
      "24/24 [==============================] - 2s 57ms/step\n",
      "Epoch 1/10\n",
      "77/77 [==============================] - 11s 136ms/step - loss: 0.5124 - acc: 0.8201 - val_loss: 0.3145 - val_acc: 0.8864\n",
      "Epoch 2/10\n",
      "77/77 [==============================] - 10s 136ms/step - loss: 0.2855 - acc: 0.8990 - val_loss: 0.2684 - val_acc: 0.8999\n",
      "Epoch 3/10\n",
      "77/77 [==============================] - 11s 138ms/step - loss: 0.2501 - acc: 0.9108 - val_loss: 0.2541 - val_acc: 0.9082\n",
      "Epoch 4/10\n",
      "77/77 [==============================] - 11s 138ms/step - loss: 0.2241 - acc: 0.9187 - val_loss: 0.2339 - val_acc: 0.9131\n",
      "Epoch 5/10\n",
      "77/77 [==============================] - 11s 142ms/step - loss: 0.2072 - acc: 0.9236 - val_loss: 0.2443 - val_acc: 0.9084\n",
      "Epoch 6/10\n",
      "77/77 [==============================] - 11s 142ms/step - loss: 0.1915 - acc: 0.9299 - val_loss: 0.2179 - val_acc: 0.9208\n",
      "Epoch 7/10\n",
      "77/77 [==============================] - 11s 142ms/step - loss: 0.1732 - acc: 0.9363 - val_loss: 0.2128 - val_acc: 0.9202\n",
      "Epoch 8/10\n",
      "77/77 [==============================] - 11s 141ms/step - loss: 0.1654 - acc: 0.9402 - val_loss: 0.2117 - val_acc: 0.9204\n",
      "Epoch 9/10\n",
      "77/77 [==============================] - 11s 144ms/step - loss: 0.1495 - acc: 0.9446 - val_loss: 0.2145 - val_acc: 0.9235\n",
      "Epoch 10/10\n",
      "77/77 [==============================] - 11s 143ms/step - loss: 0.1393 - acc: 0.9482 - val_loss: 0.2156 - val_acc: 0.9225\n",
      "24/24 [==============================] - 2s 61ms/step\n",
      "Epoch 1/10\n",
      "77/77 [==============================] - 12s 143ms/step - loss: 0.5020 - acc: 0.8223 - val_loss: 0.3139 - val_acc: 0.8864\n",
      "Epoch 2/10\n",
      "77/77 [==============================] - 11s 143ms/step - loss: 0.2874 - acc: 0.8950 - val_loss: 0.2643 - val_acc: 0.9015\n",
      "Epoch 3/10\n",
      "77/77 [==============================] - 11s 145ms/step - loss: 0.2537 - acc: 0.9080 - val_loss: 0.2520 - val_acc: 0.9054\n",
      "Epoch 4/10\n",
      "77/77 [==============================] - 11s 145ms/step - loss: 0.2292 - acc: 0.9168 - val_loss: 0.2389 - val_acc: 0.9123\n",
      "Epoch 5/10\n",
      "77/77 [==============================] - 11s 144ms/step - loss: 0.2115 - acc: 0.9234 - val_loss: 0.2469 - val_acc: 0.9129\n",
      "Epoch 6/10\n",
      "77/77 [==============================] - 11s 144ms/step - loss: 0.1959 - acc: 0.9300 - val_loss: 0.2259 - val_acc: 0.9180\n",
      "Epoch 7/10\n",
      "77/77 [==============================] - 11s 147ms/step - loss: 0.1767 - acc: 0.9354 - val_loss: 0.2339 - val_acc: 0.9160\n",
      "Epoch 8/10\n",
      "77/77 [==============================] - 11s 146ms/step - loss: 0.1665 - acc: 0.9390 - val_loss: 0.2183 - val_acc: 0.9223\n",
      "Epoch 9/10\n",
      "77/77 [==============================] - 11s 145ms/step - loss: 0.1545 - acc: 0.9431 - val_loss: 0.2186 - val_acc: 0.9206\n",
      "Epoch 10/10\n",
      "77/77 [==============================] - 11s 147ms/step - loss: 0.1408 - acc: 0.9478 - val_loss: 0.2175 - val_acc: 0.9210\n",
      "24/24 [==============================] - 2s 62ms/step\n",
      "Epoch 1/10\n",
      "77/77 [==============================] - 12s 145ms/step - loss: 0.5081 - acc: 0.8208 - val_loss: 0.3254 - val_acc: 0.8832\n",
      "Epoch 2/10\n",
      "77/77 [==============================] - 11s 145ms/step - loss: 0.2867 - acc: 0.8980 - val_loss: 0.2836 - val_acc: 0.8946\n",
      "Epoch 3/10\n",
      "77/77 [==============================] - 11s 145ms/step - loss: 0.2512 - acc: 0.9122 - val_loss: 0.2493 - val_acc: 0.9072\n",
      "Epoch 4/10\n",
      "77/77 [==============================] - 11s 147ms/step - loss: 0.2247 - acc: 0.9196 - val_loss: 0.2317 - val_acc: 0.9141\n",
      "Epoch 5/10\n",
      "77/77 [==============================] - 11s 147ms/step - loss: 0.2064 - acc: 0.9269 - val_loss: 0.2246 - val_acc: 0.9178\n",
      "Epoch 6/10\n",
      "77/77 [==============================] - 11s 147ms/step - loss: 0.1902 - acc: 0.9318 - val_loss: 0.2186 - val_acc: 0.9180\n",
      "Epoch 7/10\n",
      "77/77 [==============================] - 11s 147ms/step - loss: 0.1720 - acc: 0.9376 - val_loss: 0.2126 - val_acc: 0.9231\n",
      "Epoch 8/10\n",
      "77/77 [==============================] - 11s 148ms/step - loss: 0.1585 - acc: 0.9415 - val_loss: 0.2097 - val_acc: 0.9214\n",
      "Epoch 9/10\n",
      "77/77 [==============================] - 11s 148ms/step - loss: 0.1485 - acc: 0.9467 - val_loss: 0.2118 - val_acc: 0.9233\n",
      "Epoch 10/10\n",
      "77/77 [==============================] - 11s 147ms/step - loss: 0.1386 - acc: 0.9493 - val_loss: 0.2157 - val_acc: 0.9237\n",
      "24/24 [==============================] - 2s 62ms/step\n",
      "Epoch 1/10\n",
      "77/77 [==============================] - 13s 153ms/step - loss: 0.5099 - acc: 0.8197 - val_loss: 0.2966 - val_acc: 0.8966\n",
      "Epoch 2/10\n",
      "77/77 [==============================] - 12s 156ms/step - loss: 0.2839 - acc: 0.8993 - val_loss: 0.2538 - val_acc: 0.9074\n",
      "Epoch 3/10\n",
      "77/77 [==============================] - 12s 151ms/step - loss: 0.2500 - acc: 0.9118 - val_loss: 0.2429 - val_acc: 0.9119\n",
      "Epoch 4/10\n",
      "77/77 [==============================] - 12s 156ms/step - loss: 0.2240 - acc: 0.9178 - val_loss: 0.2391 - val_acc: 0.9151\n",
      "Epoch 5/10\n",
      "77/77 [==============================] - 11s 149ms/step - loss: 0.1996 - acc: 0.9294 - val_loss: 0.2294 - val_acc: 0.9141\n",
      "Epoch 6/10\n",
      "77/77 [==============================] - 11s 149ms/step - loss: 0.1888 - acc: 0.9310 - val_loss: 0.2192 - val_acc: 0.9212\n",
      "Epoch 7/10\n",
      "77/77 [==============================] - 11s 149ms/step - loss: 0.1733 - acc: 0.9364 - val_loss: 0.2181 - val_acc: 0.9210\n",
      "Epoch 8/10\n",
      "77/77 [==============================] - 11s 147ms/step - loss: 0.1624 - acc: 0.9416 - val_loss: 0.2104 - val_acc: 0.9231\n",
      "Epoch 9/10\n",
      "77/77 [==============================] - 12s 150ms/step - loss: 0.1475 - acc: 0.9474 - val_loss: 0.2242 - val_acc: 0.9210\n",
      "Epoch 10/10\n",
      "77/77 [==============================] - 12s 153ms/step - loss: 0.1400 - acc: 0.9492 - val_loss: 0.2199 - val_acc: 0.9214\n",
      "24/24 [==============================] - 2s 63ms/step\n",
      "Epoch 1/5\n",
      "77/77 [==============================] - 3s 34ms/step - loss: 0.9930 - acc: 0.6591 - val_loss: 0.4802 - val_acc: 0.8502\n",
      "Epoch 2/5\n",
      "77/77 [==============================] - 3s 34ms/step - loss: 0.3889 - acc: 0.8749 - val_loss: 0.3256 - val_acc: 0.8891\n",
      "Epoch 3/5\n",
      "77/77 [==============================] - 3s 34ms/step - loss: 0.3046 - acc: 0.8988 - val_loss: 0.2877 - val_acc: 0.8991\n",
      "Epoch 4/5\n",
      "77/77 [==============================] - 3s 34ms/step - loss: 0.2692 - acc: 0.9086 - val_loss: 0.2670 - val_acc: 0.9082\n",
      "Epoch 5/5\n",
      "77/77 [==============================] - 3s 34ms/step - loss: 0.2501 - acc: 0.9153 - val_loss: 0.2579 - val_acc: 0.9127\n",
      "24/24 [==============================] - 0s 8ms/step\n",
      "Epoch 1/5\n",
      "77/77 [==============================] - 3s 34ms/step - loss: 0.9643 - acc: 0.6654 - val_loss: 0.4644 - val_acc: 0.8537\n",
      "Epoch 2/5\n",
      "77/77 [==============================] - 2s 32ms/step - loss: 0.3820 - acc: 0.8772 - val_loss: 0.3330 - val_acc: 0.8869\n",
      "Epoch 3/5\n",
      "77/77 [==============================] - 2s 32ms/step - loss: 0.3023 - acc: 0.8971 - val_loss: 0.3086 - val_acc: 0.8921\n",
      "Epoch 4/5\n",
      "77/77 [==============================] - 2s 32ms/step - loss: 0.2732 - acc: 0.9058 - val_loss: 0.2812 - val_acc: 0.9003\n",
      "Epoch 5/5\n",
      "77/77 [==============================] - 2s 32ms/step - loss: 0.2502 - acc: 0.9140 - val_loss: 0.2658 - val_acc: 0.9050\n",
      "24/24 [==============================] - 0s 10ms/step\n",
      "Epoch 1/5\n",
      "77/77 [==============================] - 4s 32ms/step - loss: 1.0095 - acc: 0.6558 - val_loss: 0.4652 - val_acc: 0.8482\n",
      "Epoch 2/5\n",
      "77/77 [==============================] - 2s 32ms/step - loss: 0.3877 - acc: 0.8728 - val_loss: 0.3316 - val_acc: 0.8846\n",
      "Epoch 3/5\n",
      "77/77 [==============================] - 2s 29ms/step - loss: 0.3095 - acc: 0.8953 - val_loss: 0.2900 - val_acc: 0.8987\n",
      "Epoch 4/5\n",
      "77/77 [==============================] - 2s 31ms/step - loss: 0.2755 - acc: 0.9053 - val_loss: 0.2671 - val_acc: 0.9052\n",
      "Epoch 5/5\n",
      "77/77 [==============================] - 2s 32ms/step - loss: 0.2518 - acc: 0.9124 - val_loss: 0.2526 - val_acc: 0.9094\n",
      "24/24 [==============================] - 0s 10ms/step\n",
      "Epoch 1/5\n",
      "77/77 [==============================] - 4s 34ms/step - loss: 0.9632 - acc: 0.6517 - val_loss: 0.4470 - val_acc: 0.8539\n",
      "Epoch 2/5\n",
      "77/77 [==============================] - 2s 31ms/step - loss: 0.3895 - acc: 0.8731 - val_loss: 0.3275 - val_acc: 0.8862\n",
      "Epoch 3/5\n",
      "77/77 [==============================] - 2s 31ms/step - loss: 0.3065 - acc: 0.8973 - val_loss: 0.2865 - val_acc: 0.8966\n",
      "Epoch 4/5\n",
      "77/77 [==============================] - 2s 30ms/step - loss: 0.2733 - acc: 0.9046 - val_loss: 0.2667 - val_acc: 0.9035\n",
      "Epoch 5/5\n",
      "77/77 [==============================] - 2s 31ms/step - loss: 0.2533 - acc: 0.9127 - val_loss: 0.2526 - val_acc: 0.9101\n",
      "24/24 [==============================] - 0s 8ms/step\n",
      "Epoch 1/5\n",
      "77/77 [==============================] - 3s 32ms/step - loss: 0.9546 - acc: 0.6654 - val_loss: 0.4396 - val_acc: 0.8578\n",
      "Epoch 2/5\n",
      "77/77 [==============================] - 2s 31ms/step - loss: 0.3776 - acc: 0.8766 - val_loss: 0.3141 - val_acc: 0.8948\n",
      "Epoch 3/5\n",
      "77/77 [==============================] - 2s 30ms/step - loss: 0.3064 - acc: 0.8947 - val_loss: 0.2773 - val_acc: 0.9042\n",
      "Epoch 4/5\n",
      "77/77 [==============================] - 2s 31ms/step - loss: 0.2704 - acc: 0.9075 - val_loss: 0.2613 - val_acc: 0.9074\n",
      "Epoch 5/5\n",
      "77/77 [==============================] - 2s 30ms/step - loss: 0.2511 - acc: 0.9122 - val_loss: 0.2485 - val_acc: 0.9129\n",
      "24/24 [==============================] - 0s 9ms/step\n",
      "Epoch 1/10\n",
      "154/154 [==============================] - 6s 31ms/step - loss: 0.5728 - acc: 0.8030 - val_loss: 0.3014 - val_acc: 0.8952\n",
      "Epoch 2/10\n",
      "154/154 [==============================] - 5s 31ms/step - loss: 0.2724 - acc: 0.9054 - val_loss: 0.2640 - val_acc: 0.9048\n",
      "Epoch 3/10\n",
      "154/154 [==============================] - 5s 31ms/step - loss: 0.2339 - acc: 0.9164 - val_loss: 0.2438 - val_acc: 0.9125\n",
      "Epoch 4/10\n",
      "154/154 [==============================] - 5s 31ms/step - loss: 0.2097 - acc: 0.9258 - val_loss: 0.2346 - val_acc: 0.9155\n",
      "Epoch 5/10\n",
      "154/154 [==============================] - 5s 33ms/step - loss: 0.1906 - acc: 0.9331 - val_loss: 0.2261 - val_acc: 0.9172\n",
      "Epoch 6/10\n",
      "154/154 [==============================] - 5s 30ms/step - loss: 0.1797 - acc: 0.9353 - val_loss: 0.2171 - val_acc: 0.9188\n",
      "Epoch 7/10\n",
      "154/154 [==============================] - 5s 29ms/step - loss: 0.1676 - acc: 0.9395 - val_loss: 0.2152 - val_acc: 0.9227\n",
      "Epoch 8/10\n",
      "154/154 [==============================] - 5s 30ms/step - loss: 0.1594 - acc: 0.9437 - val_loss: 0.2099 - val_acc: 0.9231\n",
      "Epoch 9/10\n",
      "154/154 [==============================] - 5s 30ms/step - loss: 0.1430 - acc: 0.9481 - val_loss: 0.2169 - val_acc: 0.9237\n",
      "Epoch 10/10\n",
      "154/154 [==============================] - 5s 30ms/step - loss: 0.1374 - acc: 0.9509 - val_loss: 0.2124 - val_acc: 0.9229\n",
      "48/48 [==============================] - 1s 9ms/step\n",
      "Epoch 1/10\n",
      "154/154 [==============================] - 6s 31ms/step - loss: 0.5436 - acc: 0.8082 - val_loss: 0.3028 - val_acc: 0.8964\n",
      "Epoch 2/10\n",
      "154/154 [==============================] - 5s 31ms/step - loss: 0.2722 - acc: 0.9050 - val_loss: 0.2697 - val_acc: 0.9001\n",
      "Epoch 3/10\n",
      "154/154 [==============================] - 5s 31ms/step - loss: 0.2325 - acc: 0.9180 - val_loss: 0.2483 - val_acc: 0.9092\n",
      "Epoch 4/10\n",
      "154/154 [==============================] - 5s 31ms/step - loss: 0.2102 - acc: 0.9263 - val_loss: 0.2351 - val_acc: 0.9145\n",
      "Epoch 5/10\n",
      "154/154 [==============================] - 5s 31ms/step - loss: 0.1917 - acc: 0.9324 - val_loss: 0.2348 - val_acc: 0.9141\n",
      "Epoch 6/10\n",
      "154/154 [==============================] - 5s 31ms/step - loss: 0.1788 - acc: 0.9358 - val_loss: 0.2198 - val_acc: 0.9162\n",
      "Epoch 7/10\n",
      "154/154 [==============================] - 5s 30ms/step - loss: 0.1640 - acc: 0.9426 - val_loss: 0.2197 - val_acc: 0.9206\n",
      "Epoch 8/10\n",
      "154/154 [==============================] - 5s 30ms/step - loss: 0.1562 - acc: 0.9449 - val_loss: 0.2307 - val_acc: 0.9184\n",
      "Epoch 9/10\n",
      "154/154 [==============================] - 5s 31ms/step - loss: 0.1447 - acc: 0.9474 - val_loss: 0.2225 - val_acc: 0.9210\n",
      "Epoch 10/10\n",
      "154/154 [==============================] - 5s 30ms/step - loss: 0.1365 - acc: 0.9520 - val_loss: 0.2183 - val_acc: 0.9231\n",
      "48/48 [==============================] - 1s 10ms/step\n",
      "Epoch 1/10\n",
      "154/154 [==============================] - 6s 31ms/step - loss: 0.5440 - acc: 0.8121 - val_loss: 0.3021 - val_acc: 0.8930\n",
      "Epoch 2/10\n",
      "154/154 [==============================] - 5s 31ms/step - loss: 0.2706 - acc: 0.9051 - val_loss: 0.2646 - val_acc: 0.9062\n",
      "Epoch 3/10\n",
      "154/154 [==============================] - 5s 30ms/step - loss: 0.2323 - acc: 0.9180 - val_loss: 0.2526 - val_acc: 0.9113\n",
      "Epoch 4/10\n",
      "154/154 [==============================] - 5s 30ms/step - loss: 0.2083 - acc: 0.9266 - val_loss: 0.2363 - val_acc: 0.9164\n",
      "Epoch 5/10\n",
      "154/154 [==============================] - 5s 31ms/step - loss: 0.1906 - acc: 0.9323 - val_loss: 0.2311 - val_acc: 0.9153\n",
      "Epoch 6/10\n",
      "154/154 [==============================] - 5s 31ms/step - loss: 0.1768 - acc: 0.9358 - val_loss: 0.2252 - val_acc: 0.9176\n",
      "Epoch 7/10\n",
      "154/154 [==============================] - 5s 30ms/step - loss: 0.1650 - acc: 0.9421 - val_loss: 0.2298 - val_acc: 0.9172\n",
      "Epoch 8/10\n",
      "154/154 [==============================] - 4s 28ms/step - loss: 0.1534 - acc: 0.9446 - val_loss: 0.2238 - val_acc: 0.9188\n",
      "Epoch 9/10\n",
      "154/154 [==============================] - 4s 28ms/step - loss: 0.1457 - acc: 0.9478 - val_loss: 0.2275 - val_acc: 0.9204\n",
      "Epoch 10/10\n",
      "154/154 [==============================] - 4s 28ms/step - loss: 0.1349 - acc: 0.9504 - val_loss: 0.2225 - val_acc: 0.9200\n",
      "48/48 [==============================] - 1s 9ms/step\n",
      "Epoch 1/10\n",
      "154/154 [==============================] - 5s 29ms/step - loss: 0.5494 - acc: 0.8133 - val_loss: 0.3023 - val_acc: 0.8909\n",
      "Epoch 2/10\n",
      "154/154 [==============================] - 4s 29ms/step - loss: 0.2773 - acc: 0.9044 - val_loss: 0.2584 - val_acc: 0.9076\n",
      "Epoch 3/10\n",
      "154/154 [==============================] - 4s 29ms/step - loss: 0.2370 - acc: 0.9180 - val_loss: 0.2407 - val_acc: 0.9149\n",
      "Epoch 4/10\n",
      "154/154 [==============================] - 4s 29ms/step - loss: 0.2125 - acc: 0.9257 - val_loss: 0.2272 - val_acc: 0.9164\n",
      "Epoch 5/10\n",
      "154/154 [==============================] - 4s 29ms/step - loss: 0.1941 - acc: 0.9295 - val_loss: 0.2321 - val_acc: 0.9160\n",
      "Epoch 6/10\n",
      "154/154 [==============================] - 4s 29ms/step - loss: 0.1789 - acc: 0.9358 - val_loss: 0.2208 - val_acc: 0.9194\n",
      "Epoch 7/10\n",
      "154/154 [==============================] - 4s 29ms/step - loss: 0.1667 - acc: 0.9412 - val_loss: 0.2188 - val_acc: 0.9188\n",
      "Epoch 8/10\n",
      "154/154 [==============================] - 4s 29ms/step - loss: 0.1548 - acc: 0.9451 - val_loss: 0.2142 - val_acc: 0.9225\n",
      "Epoch 9/10\n",
      "154/154 [==============================] - 4s 28ms/step - loss: 0.1437 - acc: 0.9500 - val_loss: 0.2125 - val_acc: 0.9200\n",
      "Epoch 10/10\n",
      "154/154 [==============================] - 4s 29ms/step - loss: 0.1363 - acc: 0.9519 - val_loss: 0.2175 - val_acc: 0.9237\n",
      "48/48 [==============================] - 1s 9ms/step\n",
      "Epoch 1/10\n",
      "154/154 [==============================] - 5s 28ms/step - loss: 0.5665 - acc: 0.8000 - val_loss: 0.3042 - val_acc: 0.8936\n",
      "Epoch 2/10\n",
      "154/154 [==============================] - 4s 27ms/step - loss: 0.2789 - acc: 0.9030 - val_loss: 0.2610 - val_acc: 0.9058\n",
      "Epoch 3/10\n",
      "154/154 [==============================] - 4s 27ms/step - loss: 0.2335 - acc: 0.9200 - val_loss: 0.2402 - val_acc: 0.9094\n",
      "Epoch 4/10\n",
      "154/154 [==============================] - 4s 27ms/step - loss: 0.2103 - acc: 0.9279 - val_loss: 0.2383 - val_acc: 0.9125\n",
      "Epoch 5/10\n",
      "154/154 [==============================] - 4s 27ms/step - loss: 0.1946 - acc: 0.9316 - val_loss: 0.2192 - val_acc: 0.9202\n",
      "Epoch 6/10\n",
      "154/154 [==============================] - 4s 27ms/step - loss: 0.1788 - acc: 0.9364 - val_loss: 0.2164 - val_acc: 0.9214\n",
      "Epoch 7/10\n",
      "154/154 [==============================] - 4s 27ms/step - loss: 0.1635 - acc: 0.9413 - val_loss: 0.2220 - val_acc: 0.9223\n",
      "Epoch 8/10\n",
      "154/154 [==============================] - 4s 28ms/step - loss: 0.1535 - acc: 0.9452 - val_loss: 0.2160 - val_acc: 0.9212\n",
      "Epoch 9/10\n",
      "154/154 [==============================] - 4s 28ms/step - loss: 0.1432 - acc: 0.9474 - val_loss: 0.2191 - val_acc: 0.9231\n",
      "Epoch 10/10\n",
      "154/154 [==============================] - 4s 28ms/step - loss: 0.1365 - acc: 0.9510 - val_loss: 0.2272 - val_acc: 0.9243\n",
      "48/48 [==============================] - 1s 9ms/step\n",
      "Epoch 1/5\n",
      "Epoch 1/5\n",
      "Epoch 1/5\n",
      "Epoch 1/5\n",
      "Epoch 1/5\n",
      "Epoch 1/5\n",
      "308/308 [==============================] - 18s 55ms/step - loss: 0.3792 - acc: 0.8700 - val_loss: 0.2810 - val_acc: 0.9003\n",
      "Epoch 2/5\n",
      "308/308 [==============================] - 19s 62ms/step - loss: 0.2428 - acc: 0.9158 - val_loss: 0.2465 - val_acc: 0.9129\n",
      "Epoch 3/5\n",
      "308/308 [==============================] - 18s 59ms/step - loss: 0.1999 - acc: 0.9287 - val_loss: 0.2209 - val_acc: 0.9178\n",
      "Epoch 4/5\n",
      "308/308 [==============================] - 17s 56ms/step - loss: 0.1743 - acc: 0.9382 - val_loss: 0.2124 - val_acc: 0.9214\n",
      "Epoch 5/5\n",
      "308/308 [==============================] - 17s 56ms/step - loss: 0.1523 - acc: 0.9440 - val_loss: 0.2172 - val_acc: 0.9233\n",
      "96/96 [==============================] - 2s 22ms/step\n",
      "Epoch 1/5\n",
      "308/308 [==============================] - 18s 55ms/step - loss: 0.3799 - acc: 0.8672 - val_loss: 0.2702 - val_acc: 0.9054\n",
      "Epoch 2/5\n",
      "308/308 [==============================] - 18s 60ms/step - loss: 0.2437 - acc: 0.9132 - val_loss: 0.2498 - val_acc: 0.9090\n",
      "Epoch 3/5\n",
      "308/308 [==============================] - 17s 54ms/step - loss: 0.2007 - acc: 0.9284 - val_loss: 0.2240 - val_acc: 0.9170\n",
      "Epoch 4/5\n",
      "308/308 [==============================] - 18s 58ms/step - loss: 0.1727 - acc: 0.9381 - val_loss: 0.2246 - val_acc: 0.9206\n",
      "Epoch 5/5\n",
      "308/308 [==============================] - 17s 55ms/step - loss: 0.1535 - acc: 0.9437 - val_loss: 0.2182 - val_acc: 0.9229\n",
      "96/96 [==============================] - 2s 20ms/step\n",
      "Epoch 1/5\n",
      "308/308 [==============================] - 18s 54ms/step - loss: 0.3822 - acc: 0.8637 - val_loss: 0.2814 - val_acc: 0.8997\n",
      "Epoch 2/5\n",
      "308/308 [==============================] - 18s 59ms/step - loss: 0.2469 - acc: 0.9114 - val_loss: 0.2659 - val_acc: 0.9035\n",
      "Epoch 3/5\n",
      "308/308 [==============================] - 18s 60ms/step - loss: 0.2110 - acc: 0.9246 - val_loss: 0.2232 - val_acc: 0.9184\n",
      "Epoch 4/5\n",
      "308/308 [==============================] - 18s 58ms/step - loss: 0.1758 - acc: 0.9353 - val_loss: 0.2336 - val_acc: 0.9153\n",
      "Epoch 5/5\n",
      "308/308 [==============================] - 18s 59ms/step - loss: 0.1573 - acc: 0.9436 - val_loss: 0.2091 - val_acc: 0.9227\n",
      "96/96 [==============================] - 3s 25ms/step\n",
      "Epoch 1/5\n",
      "308/308 [==============================] - 20s 62ms/step - loss: 0.3868 - acc: 0.8627 - val_loss: 0.2721 - val_acc: 0.8999\n",
      "Epoch 2/5\n",
      "308/308 [==============================] - 19s 62ms/step - loss: 0.2442 - acc: 0.9145 - val_loss: 0.2285 - val_acc: 0.9164\n",
      "Epoch 3/5\n",
      "308/308 [==============================] - 18s 59ms/step - loss: 0.2052 - acc: 0.9270 - val_loss: 0.2259 - val_acc: 0.9188\n",
      "Epoch 4/5\n",
      "308/308 [==============================] - 18s 60ms/step - loss: 0.1751 - acc: 0.9368 - val_loss: 0.2103 - val_acc: 0.9223\n",
      "Epoch 5/5\n",
      "308/308 [==============================] - 19s 62ms/step - loss: 0.1542 - acc: 0.9447 - val_loss: 0.2150 - val_acc: 0.9231\n",
      "96/96 [==============================] - 3s 27ms/step\n",
      "Epoch 1/5\n",
      "308/308 [==============================] - 19s 60ms/step - loss: 0.3805 - acc: 0.8679 - val_loss: 0.2617 - val_acc: 0.9052\n",
      "Epoch 2/5\n",
      "308/308 [==============================] - 18s 60ms/step - loss: 0.2444 - acc: 0.9137 - val_loss: 0.2357 - val_acc: 0.9170\n",
      "Epoch 3/5\n",
      "308/308 [==============================] - 18s 59ms/step - loss: 0.2012 - acc: 0.9283 - val_loss: 0.2255 - val_acc: 0.9180\n",
      "Epoch 4/5\n",
      "308/308 [==============================] - 18s 60ms/step - loss: 0.1742 - acc: 0.9370 - val_loss: 0.2090 - val_acc: 0.9237\n",
      "Epoch 5/5\n",
      "308/308 [==============================] - 18s 59ms/step - loss: 0.1529 - acc: 0.9445 - val_loss: 0.2095 - val_acc: 0.9241\n",
      "96/96 [==============================] - 2s 21ms/step\n",
      "Epoch 1/10\n",
      "615/615 [==============================] - 18s 27ms/step - loss: 0.3582 - acc: 0.8755 - val_loss: 0.2715 - val_acc: 0.9039\n",
      "Epoch 2/10\n",
      "615/615 [==============================] - 16s 25ms/step - loss: 0.2161 - acc: 0.9254 - val_loss: 0.2275 - val_acc: 0.9162\n",
      "Epoch 3/10\n",
      "615/615 [==============================] - 16s 25ms/step - loss: 0.1773 - acc: 0.9358 - val_loss: 0.2164 - val_acc: 0.9194\n",
      "Epoch 4/10\n",
      "615/615 [==============================] - 15s 25ms/step - loss: 0.1519 - acc: 0.9473 - val_loss: 0.2096 - val_acc: 0.9214\n",
      "Epoch 5/10\n",
      "615/615 [==============================] - 15s 25ms/step - loss: 0.1261 - acc: 0.9549 - val_loss: 0.2262 - val_acc: 0.9139\n",
      "Epoch 6/10\n",
      "615/615 [==============================] - 16s 25ms/step - loss: 0.1045 - acc: 0.9617 - val_loss: 0.2244 - val_acc: 0.9227\n",
      "Epoch 7/10\n",
      "615/615 [==============================] - 16s 25ms/step - loss: 0.0840 - acc: 0.9696 - val_loss: 0.2440 - val_acc: 0.9180\n",
      "Epoch 8/10\n",
      "615/615 [==============================] - 15s 25ms/step - loss: 0.0626 - acc: 0.9781 - val_loss: 0.2595 - val_acc: 0.9164\n",
      "Epoch 9/10\n",
      "615/615 [==============================] - 15s 25ms/step - loss: 0.0506 - acc: 0.9839 - val_loss: 0.2614 - val_acc: 0.9204\n",
      "Epoch 10/10\n",
      "615/615 [==============================] - 15s 25ms/step - loss: 0.0392 - acc: 0.9880 - val_loss: 0.2839 - val_acc: 0.9162\n",
      "192/192 [==============================] - 2s 8ms/step\n",
      "Epoch 1/10\n",
      "615/615 [==============================] - 17s 26ms/step - loss: 0.3567 - acc: 0.8761 - val_loss: 0.2584 - val_acc: 0.9080\n",
      "Epoch 2/10\n",
      "615/615 [==============================] - 16s 26ms/step - loss: 0.2198 - acc: 0.9227 - val_loss: 0.2355 - val_acc: 0.9158\n",
      "Epoch 3/10\n",
      "615/615 [==============================] - 16s 26ms/step - loss: 0.1814 - acc: 0.9355 - val_loss: 0.2394 - val_acc: 0.9153\n",
      "Epoch 4/10\n",
      "615/615 [==============================] - 16s 26ms/step - loss: 0.1529 - acc: 0.9450 - val_loss: 0.2172 - val_acc: 0.9221\n",
      "Epoch 5/10\n",
      "615/615 [==============================] - 16s 26ms/step - loss: 0.1317 - acc: 0.9527 - val_loss: 0.2124 - val_acc: 0.9265\n",
      "Epoch 6/10\n",
      "615/615 [==============================] - 16s 26ms/step - loss: 0.1086 - acc: 0.9606 - val_loss: 0.2272 - val_acc: 0.9221\n",
      "Epoch 7/10\n",
      "615/615 [==============================] - 16s 25ms/step - loss: 0.0885 - acc: 0.9675 - val_loss: 0.2308 - val_acc: 0.9208\n",
      "Epoch 8/10\n",
      "615/615 [==============================] - 16s 26ms/step - loss: 0.0676 - acc: 0.9767 - val_loss: 0.2371 - val_acc: 0.9208\n",
      "Epoch 9/10\n",
      "615/615 [==============================] - 16s 25ms/step - loss: 0.0517 - acc: 0.9826 - val_loss: 0.2851 - val_acc: 0.9153\n",
      "Epoch 10/10\n",
      "615/615 [==============================] - 16s 25ms/step - loss: 0.0428 - acc: 0.9854 - val_loss: 0.2805 - val_acc: 0.9180\n",
      "192/192 [==============================] - 2s 8ms/step\n",
      "Epoch 1/10\n",
      "615/615 [==============================] - 17s 26ms/step - loss: 0.3618 - acc: 0.8731 - val_loss: 0.2827 - val_acc: 0.8932\n",
      "Epoch 2/10\n",
      "615/615 [==============================] - 16s 27ms/step - loss: 0.2244 - acc: 0.9199 - val_loss: 0.2340 - val_acc: 0.9149\n",
      "Epoch 3/10\n",
      "615/615 [==============================] - 15s 24ms/step - loss: 0.1851 - acc: 0.9344 - val_loss: 0.2171 - val_acc: 0.9217\n",
      "Epoch 4/10\n",
      "615/615 [==============================] - 15s 24ms/step - loss: 0.1528 - acc: 0.9434 - val_loss: 0.2175 - val_acc: 0.9214\n",
      "Epoch 5/10\n",
      "615/615 [==============================] - 15s 24ms/step - loss: 0.1336 - acc: 0.9501 - val_loss: 0.2116 - val_acc: 0.9227\n",
      "Epoch 6/10\n",
      "615/615 [==============================] - 15s 24ms/step - loss: 0.1088 - acc: 0.9624 - val_loss: 0.2266 - val_acc: 0.9223\n",
      "Epoch 7/10\n",
      "615/615 [==============================] - 15s 25ms/step - loss: 0.0866 - acc: 0.9692 - val_loss: 0.2550 - val_acc: 0.9194\n",
      "Epoch 8/10\n",
      "615/615 [==============================] - 15s 24ms/step - loss: 0.0716 - acc: 0.9750 - val_loss: 0.2511 - val_acc: 0.9188\n",
      "Epoch 9/10\n",
      "615/615 [==============================] - 15s 24ms/step - loss: 0.0567 - acc: 0.9812 - val_loss: 0.2755 - val_acc: 0.9231\n",
      "Epoch 10/10\n",
      "615/615 [==============================] - 15s 24ms/step - loss: 0.0416 - acc: 0.9865 - val_loss: 0.3014 - val_acc: 0.9198\n",
      "192/192 [==============================] - 2s 7ms/step\n",
      "Epoch 1/10\n",
      "615/615 [==============================] - 16s 24ms/step - loss: 0.3599 - acc: 0.8752 - val_loss: 0.2764 - val_acc: 0.9039\n",
      "Epoch 2/10\n",
      "615/615 [==============================] - 15s 25ms/step - loss: 0.2196 - acc: 0.9245 - val_loss: 0.2365 - val_acc: 0.9158\n",
      "Epoch 3/10\n",
      "615/615 [==============================] - 15s 24ms/step - loss: 0.1803 - acc: 0.9367 - val_loss: 0.2099 - val_acc: 0.9245\n",
      "Epoch 4/10\n",
      "615/615 [==============================] - 15s 25ms/step - loss: 0.1515 - acc: 0.9455 - val_loss: 0.2131 - val_acc: 0.9217\n",
      "Epoch 5/10\n",
      "615/615 [==============================] - 15s 24ms/step - loss: 0.1279 - acc: 0.9550 - val_loss: 0.2077 - val_acc: 0.9233\n",
      "Epoch 6/10\n",
      "615/615 [==============================] - 15s 24ms/step - loss: 0.1063 - acc: 0.9629 - val_loss: 0.2517 - val_acc: 0.9162\n",
      "Epoch 7/10\n",
      "615/615 [==============================] - 15s 24ms/step - loss: 0.0873 - acc: 0.9695 - val_loss: 0.2443 - val_acc: 0.9204\n",
      "Epoch 8/10\n",
      "615/615 [==============================] - 15s 25ms/step - loss: 0.0637 - acc: 0.9788 - val_loss: 0.2534 - val_acc: 0.9180\n",
      "Epoch 9/10\n",
      "615/615 [==============================] - 15s 24ms/step - loss: 0.0537 - acc: 0.9814 - val_loss: 0.2688 - val_acc: 0.9182\n",
      "Epoch 10/10\n",
      "615/615 [==============================] - 15s 25ms/step - loss: 0.0380 - acc: 0.9885 - val_loss: 0.2993 - val_acc: 0.9176\n",
      "192/192 [==============================] - 2s 8ms/step\n",
      "Epoch 1/10\n",
      "615/615 [==============================] - 16s 24ms/step - loss: 0.3675 - acc: 0.8729 - val_loss: 0.2746 - val_acc: 0.9033\n",
      "Epoch 2/10\n",
      "615/615 [==============================] - 15s 25ms/step - loss: 0.2217 - acc: 0.9214 - val_loss: 0.2318 - val_acc: 0.9190\n",
      "Epoch 3/10\n",
      "615/615 [==============================] - 16s 25ms/step - loss: 0.1821 - acc: 0.9351 - val_loss: 0.2239 - val_acc: 0.9184\n",
      "Epoch 4/10\n",
      "615/615 [==============================] - 16s 25ms/step - loss: 0.1529 - acc: 0.9451 - val_loss: 0.2171 - val_acc: 0.9217\n",
      "Epoch 5/10\n",
      "615/615 [==============================] - 15s 25ms/step - loss: 0.1297 - acc: 0.9529 - val_loss: 0.2224 - val_acc: 0.9239\n",
      "Epoch 6/10\n",
      "615/615 [==============================] - 15s 25ms/step - loss: 0.1092 - acc: 0.9609 - val_loss: 0.2451 - val_acc: 0.9206\n",
      "Epoch 7/10\n",
      "615/615 [==============================] - 15s 25ms/step - loss: 0.0872 - acc: 0.9696 - val_loss: 0.2400 - val_acc: 0.9271\n",
      "Epoch 8/10\n",
      "615/615 [==============================] - 16s 25ms/step - loss: 0.0696 - acc: 0.9754 - val_loss: 0.2509 - val_acc: 0.9241\n",
      "Epoch 9/10\n",
      "615/615 [==============================] - 16s 25ms/step - loss: 0.0512 - acc: 0.9828 - val_loss: 0.2901 - val_acc: 0.9158\n",
      "Epoch 10/10\n",
      "615/615 [==============================] - 16s 25ms/step - loss: 0.0391 - acc: 0.9876 - val_loss: 0.2906 - val_acc: 0.9237\n",
      "192/192 [==============================] - 2s 8ms/step\n"
     ]
    },
    {
     "name": "stderr",
     "output_type": "stream",
     "text": [
      "/opt/anaconda3/envs/tf_env4/lib/python3.8/site-packages/sklearn/model_selection/_validation.py:425: FitFailedWarning: \n",
      "20 fits failed out of a total of 50.\n",
      "The score on these train-test partitions for these parameters will be set to nan.\n",
      "If these failures are not expected, you can try to debug them by setting error_score='raise'.\n",
      "\n",
      "Below are more details about the failures:\n",
      "--------------------------------------------------------------------------------\n",
      "1 fits failed with the following error:\n",
      "Traceback (most recent call last):\n",
      "  File \"/opt/anaconda3/envs/tf_env4/lib/python3.8/site-packages/sklearn/model_selection/_validation.py\", line 729, in _fit_and_score\n",
      "    estimator.fit(X_train, y_train, **fit_params)\n",
      "  File \"/opt/anaconda3/envs/tf_env4/lib/python3.8/site-packages/scikeras/wrappers.py\", line 1491, in fit\n",
      "    super().fit(X=X, y=y, sample_weight=sample_weight, **kwargs)\n",
      "  File \"/opt/anaconda3/envs/tf_env4/lib/python3.8/site-packages/scikeras/wrappers.py\", line 760, in fit\n",
      "    self._fit(\n",
      "  File \"/opt/anaconda3/envs/tf_env4/lib/python3.8/site-packages/scikeras/wrappers.py\", line 928, in _fit\n",
      "    self._fit_keras_model(\n",
      "  File \"/opt/anaconda3/envs/tf_env4/lib/python3.8/site-packages/scikeras/wrappers.py\", line 524, in _fit_keras_model\n",
      "    hist = self.model_.fit(x=X, y=y, **fit_args)\n",
      "  File \"/opt/anaconda3/envs/tf_env4/lib/python3.8/site-packages/keras/src/utils/traceback_utils.py\", line 70, in error_handler\n",
      "    raise e.with_traceback(filtered_tb) from None\n",
      "  File \"/var/folders/tz/9k5bcs_502z2svd2fr_k2w680000gn/T/__autograph_generated_file05s8fla1.py\", line 15, in tf__train_function\n",
      "    retval_ = ag__.converted_call(ag__.ld(step_function), (ag__.ld(self), ag__.ld(iterator)), None, fscope)\n",
      "ValueError: in user code:\n",
      "\n",
      "    File \"/opt/anaconda3/envs/tf_env4/lib/python3.8/site-packages/keras/src/engine/training.py\", line 1338, in train_function  *\n",
      "        return step_function(self, iterator)\n",
      "    File \"/opt/anaconda3/envs/tf_env4/lib/python3.8/site-packages/keras/src/engine/training.py\", line 1322, in step_function  **\n",
      "        outputs = model.distribute_strategy.run(run_step, args=(data,))\n",
      "    File \"/opt/anaconda3/envs/tf_env4/lib/python3.8/site-packages/keras/src/engine/training.py\", line 1303, in run_step  **\n",
      "        outputs = model.train_step(data)\n",
      "    File \"/opt/anaconda3/envs/tf_env4/lib/python3.8/site-packages/keras/src/engine/training.py\", line 1080, in train_step\n",
      "        y_pred = self(x, training=True)\n",
      "    File \"/opt/anaconda3/envs/tf_env4/lib/python3.8/site-packages/keras/src/utils/traceback_utils.py\", line 70, in error_handler\n",
      "        raise e.with_traceback(filtered_tb) from None\n",
      "\n",
      "    ValueError: Exception encountered when calling layer 'dropout' (type Dropout).\n",
      "    \n",
      "    `rate` must be a scalar or scalar tensor. Received: rate=None\n",
      "    \n",
      "    Call arguments received by layer 'dropout' (type Dropout):\n",
      "      • inputs=tf.Tensor(shape=(None, 25, 200), dtype=float32)\n",
      "      • training=True\n",
      "\n",
      "\n",
      "--------------------------------------------------------------------------------\n",
      "1 fits failed with the following error:\n",
      "Traceback (most recent call last):\n",
      "  File \"/opt/anaconda3/envs/tf_env4/lib/python3.8/site-packages/sklearn/model_selection/_validation.py\", line 729, in _fit_and_score\n",
      "    estimator.fit(X_train, y_train, **fit_params)\n",
      "  File \"/opt/anaconda3/envs/tf_env4/lib/python3.8/site-packages/scikeras/wrappers.py\", line 1491, in fit\n",
      "    super().fit(X=X, y=y, sample_weight=sample_weight, **kwargs)\n",
      "  File \"/opt/anaconda3/envs/tf_env4/lib/python3.8/site-packages/scikeras/wrappers.py\", line 760, in fit\n",
      "    self._fit(\n",
      "  File \"/opt/anaconda3/envs/tf_env4/lib/python3.8/site-packages/scikeras/wrappers.py\", line 928, in _fit\n",
      "    self._fit_keras_model(\n",
      "  File \"/opt/anaconda3/envs/tf_env4/lib/python3.8/site-packages/scikeras/wrappers.py\", line 524, in _fit_keras_model\n",
      "    hist = self.model_.fit(x=X, y=y, **fit_args)\n",
      "  File \"/opt/anaconda3/envs/tf_env4/lib/python3.8/site-packages/keras/src/utils/traceback_utils.py\", line 70, in error_handler\n",
      "    raise e.with_traceback(filtered_tb) from None\n",
      "  File \"/var/folders/tz/9k5bcs_502z2svd2fr_k2w680000gn/T/__autograph_generated_file05s8fla1.py\", line 15, in tf__train_function\n",
      "    retval_ = ag__.converted_call(ag__.ld(step_function), (ag__.ld(self), ag__.ld(iterator)), None, fscope)\n",
      "ValueError: in user code:\n",
      "\n",
      "    File \"/opt/anaconda3/envs/tf_env4/lib/python3.8/site-packages/keras/src/engine/training.py\", line 1338, in train_function  *\n",
      "        return step_function(self, iterator)\n",
      "    File \"/opt/anaconda3/envs/tf_env4/lib/python3.8/site-packages/keras/src/engine/training.py\", line 1322, in step_function  **\n",
      "        outputs = model.distribute_strategy.run(run_step, args=(data,))\n",
      "    File \"/opt/anaconda3/envs/tf_env4/lib/python3.8/site-packages/keras/src/engine/training.py\", line 1303, in run_step  **\n",
      "        outputs = model.train_step(data)\n",
      "    File \"/opt/anaconda3/envs/tf_env4/lib/python3.8/site-packages/keras/src/engine/training.py\", line 1080, in train_step\n",
      "        y_pred = self(x, training=True)\n",
      "    File \"/opt/anaconda3/envs/tf_env4/lib/python3.8/site-packages/keras/src/utils/traceback_utils.py\", line 70, in error_handler\n",
      "        raise e.with_traceback(filtered_tb) from None\n",
      "\n",
      "    ValueError: Exception encountered when calling layer 'dropout_1' (type Dropout).\n",
      "    \n",
      "    `rate` must be a scalar or scalar tensor. Received: rate=None\n",
      "    \n",
      "    Call arguments received by layer 'dropout_1' (type Dropout):\n",
      "      • inputs=tf.Tensor(shape=(None, 25, 200), dtype=float32)\n",
      "      • training=True\n",
      "\n",
      "\n",
      "--------------------------------------------------------------------------------\n",
      "1 fits failed with the following error:\n",
      "Traceback (most recent call last):\n",
      "  File \"/opt/anaconda3/envs/tf_env4/lib/python3.8/site-packages/sklearn/model_selection/_validation.py\", line 729, in _fit_and_score\n",
      "    estimator.fit(X_train, y_train, **fit_params)\n",
      "  File \"/opt/anaconda3/envs/tf_env4/lib/python3.8/site-packages/scikeras/wrappers.py\", line 1491, in fit\n",
      "    super().fit(X=X, y=y, sample_weight=sample_weight, **kwargs)\n",
      "  File \"/opt/anaconda3/envs/tf_env4/lib/python3.8/site-packages/scikeras/wrappers.py\", line 760, in fit\n",
      "    self._fit(\n",
      "  File \"/opt/anaconda3/envs/tf_env4/lib/python3.8/site-packages/scikeras/wrappers.py\", line 928, in _fit\n",
      "    self._fit_keras_model(\n",
      "  File \"/opt/anaconda3/envs/tf_env4/lib/python3.8/site-packages/scikeras/wrappers.py\", line 524, in _fit_keras_model\n",
      "    hist = self.model_.fit(x=X, y=y, **fit_args)\n",
      "  File \"/opt/anaconda3/envs/tf_env4/lib/python3.8/site-packages/keras/src/utils/traceback_utils.py\", line 70, in error_handler\n",
      "    raise e.with_traceback(filtered_tb) from None\n",
      "  File \"/var/folders/tz/9k5bcs_502z2svd2fr_k2w680000gn/T/__autograph_generated_file05s8fla1.py\", line 15, in tf__train_function\n",
      "    retval_ = ag__.converted_call(ag__.ld(step_function), (ag__.ld(self), ag__.ld(iterator)), None, fscope)\n",
      "ValueError: in user code:\n",
      "\n",
      "    File \"/opt/anaconda3/envs/tf_env4/lib/python3.8/site-packages/keras/src/engine/training.py\", line 1338, in train_function  *\n",
      "        return step_function(self, iterator)\n",
      "    File \"/opt/anaconda3/envs/tf_env4/lib/python3.8/site-packages/keras/src/engine/training.py\", line 1322, in step_function  **\n",
      "        outputs = model.distribute_strategy.run(run_step, args=(data,))\n",
      "    File \"/opt/anaconda3/envs/tf_env4/lib/python3.8/site-packages/keras/src/engine/training.py\", line 1303, in run_step  **\n",
      "        outputs = model.train_step(data)\n",
      "    File \"/opt/anaconda3/envs/tf_env4/lib/python3.8/site-packages/keras/src/engine/training.py\", line 1080, in train_step\n",
      "        y_pred = self(x, training=True)\n",
      "    File \"/opt/anaconda3/envs/tf_env4/lib/python3.8/site-packages/keras/src/utils/traceback_utils.py\", line 70, in error_handler\n",
      "        raise e.with_traceback(filtered_tb) from None\n",
      "\n",
      "    ValueError: Exception encountered when calling layer 'dropout_2' (type Dropout).\n",
      "    \n",
      "    `rate` must be a scalar or scalar tensor. Received: rate=None\n",
      "    \n",
      "    Call arguments received by layer 'dropout_2' (type Dropout):\n",
      "      • inputs=tf.Tensor(shape=(None, 25, 200), dtype=float32)\n",
      "      • training=True\n",
      "\n",
      "\n",
      "--------------------------------------------------------------------------------\n",
      "1 fits failed with the following error:\n",
      "Traceback (most recent call last):\n",
      "  File \"/opt/anaconda3/envs/tf_env4/lib/python3.8/site-packages/sklearn/model_selection/_validation.py\", line 729, in _fit_and_score\n",
      "    estimator.fit(X_train, y_train, **fit_params)\n",
      "  File \"/opt/anaconda3/envs/tf_env4/lib/python3.8/site-packages/scikeras/wrappers.py\", line 1491, in fit\n",
      "    super().fit(X=X, y=y, sample_weight=sample_weight, **kwargs)\n",
      "  File \"/opt/anaconda3/envs/tf_env4/lib/python3.8/site-packages/scikeras/wrappers.py\", line 760, in fit\n",
      "    self._fit(\n",
      "  File \"/opt/anaconda3/envs/tf_env4/lib/python3.8/site-packages/scikeras/wrappers.py\", line 928, in _fit\n",
      "    self._fit_keras_model(\n",
      "  File \"/opt/anaconda3/envs/tf_env4/lib/python3.8/site-packages/scikeras/wrappers.py\", line 524, in _fit_keras_model\n",
      "    hist = self.model_.fit(x=X, y=y, **fit_args)\n",
      "  File \"/opt/anaconda3/envs/tf_env4/lib/python3.8/site-packages/keras/src/utils/traceback_utils.py\", line 70, in error_handler\n",
      "    raise e.with_traceback(filtered_tb) from None\n",
      "  File \"/var/folders/tz/9k5bcs_502z2svd2fr_k2w680000gn/T/__autograph_generated_file05s8fla1.py\", line 15, in tf__train_function\n",
      "    retval_ = ag__.converted_call(ag__.ld(step_function), (ag__.ld(self), ag__.ld(iterator)), None, fscope)\n",
      "ValueError: in user code:\n",
      "\n",
      "    File \"/opt/anaconda3/envs/tf_env4/lib/python3.8/site-packages/keras/src/engine/training.py\", line 1338, in train_function  *\n",
      "        return step_function(self, iterator)\n",
      "    File \"/opt/anaconda3/envs/tf_env4/lib/python3.8/site-packages/keras/src/engine/training.py\", line 1322, in step_function  **\n",
      "        outputs = model.distribute_strategy.run(run_step, args=(data,))\n",
      "    File \"/opt/anaconda3/envs/tf_env4/lib/python3.8/site-packages/keras/src/engine/training.py\", line 1303, in run_step  **\n",
      "        outputs = model.train_step(data)\n",
      "    File \"/opt/anaconda3/envs/tf_env4/lib/python3.8/site-packages/keras/src/engine/training.py\", line 1080, in train_step\n",
      "        y_pred = self(x, training=True)\n",
      "    File \"/opt/anaconda3/envs/tf_env4/lib/python3.8/site-packages/keras/src/utils/traceback_utils.py\", line 70, in error_handler\n",
      "        raise e.with_traceback(filtered_tb) from None\n",
      "\n",
      "    ValueError: Exception encountered when calling layer 'dropout_3' (type Dropout).\n",
      "    \n",
      "    `rate` must be a scalar or scalar tensor. Received: rate=None\n",
      "    \n",
      "    Call arguments received by layer 'dropout_3' (type Dropout):\n",
      "      • inputs=tf.Tensor(shape=(None, 25, 200), dtype=float32)\n",
      "      • training=True\n",
      "\n",
      "\n",
      "--------------------------------------------------------------------------------\n",
      "1 fits failed with the following error:\n",
      "Traceback (most recent call last):\n",
      "  File \"/opt/anaconda3/envs/tf_env4/lib/python3.8/site-packages/sklearn/model_selection/_validation.py\", line 729, in _fit_and_score\n",
      "    estimator.fit(X_train, y_train, **fit_params)\n",
      "  File \"/opt/anaconda3/envs/tf_env4/lib/python3.8/site-packages/scikeras/wrappers.py\", line 1491, in fit\n",
      "    super().fit(X=X, y=y, sample_weight=sample_weight, **kwargs)\n",
      "  File \"/opt/anaconda3/envs/tf_env4/lib/python3.8/site-packages/scikeras/wrappers.py\", line 760, in fit\n",
      "    self._fit(\n",
      "  File \"/opt/anaconda3/envs/tf_env4/lib/python3.8/site-packages/scikeras/wrappers.py\", line 928, in _fit\n",
      "    self._fit_keras_model(\n",
      "  File \"/opt/anaconda3/envs/tf_env4/lib/python3.8/site-packages/scikeras/wrappers.py\", line 524, in _fit_keras_model\n",
      "    hist = self.model_.fit(x=X, y=y, **fit_args)\n",
      "  File \"/opt/anaconda3/envs/tf_env4/lib/python3.8/site-packages/keras/src/utils/traceback_utils.py\", line 70, in error_handler\n",
      "    raise e.with_traceback(filtered_tb) from None\n",
      "  File \"/var/folders/tz/9k5bcs_502z2svd2fr_k2w680000gn/T/__autograph_generated_file05s8fla1.py\", line 15, in tf__train_function\n",
      "    retval_ = ag__.converted_call(ag__.ld(step_function), (ag__.ld(self), ag__.ld(iterator)), None, fscope)\n",
      "ValueError: in user code:\n",
      "\n",
      "    File \"/opt/anaconda3/envs/tf_env4/lib/python3.8/site-packages/keras/src/engine/training.py\", line 1338, in train_function  *\n",
      "        return step_function(self, iterator)\n",
      "    File \"/opt/anaconda3/envs/tf_env4/lib/python3.8/site-packages/keras/src/engine/training.py\", line 1322, in step_function  **\n",
      "        outputs = model.distribute_strategy.run(run_step, args=(data,))\n",
      "    File \"/opt/anaconda3/envs/tf_env4/lib/python3.8/site-packages/keras/src/engine/training.py\", line 1303, in run_step  **\n",
      "        outputs = model.train_step(data)\n",
      "    File \"/opt/anaconda3/envs/tf_env4/lib/python3.8/site-packages/keras/src/engine/training.py\", line 1080, in train_step\n",
      "        y_pred = self(x, training=True)\n",
      "    File \"/opt/anaconda3/envs/tf_env4/lib/python3.8/site-packages/keras/src/utils/traceback_utils.py\", line 70, in error_handler\n",
      "        raise e.with_traceback(filtered_tb) from None\n",
      "\n",
      "    ValueError: Exception encountered when calling layer 'dropout_4' (type Dropout).\n",
      "    \n",
      "    `rate` must be a scalar or scalar tensor. Received: rate=None\n",
      "    \n",
      "    Call arguments received by layer 'dropout_4' (type Dropout):\n",
      "      • inputs=tf.Tensor(shape=(None, 25, 200), dtype=float32)\n",
      "      • training=True\n",
      "\n",
      "\n",
      "--------------------------------------------------------------------------------\n",
      "1 fits failed with the following error:\n",
      "Traceback (most recent call last):\n",
      "  File \"/opt/anaconda3/envs/tf_env4/lib/python3.8/site-packages/sklearn/model_selection/_validation.py\", line 729, in _fit_and_score\n",
      "    estimator.fit(X_train, y_train, **fit_params)\n",
      "  File \"/opt/anaconda3/envs/tf_env4/lib/python3.8/site-packages/scikeras/wrappers.py\", line 1491, in fit\n",
      "    super().fit(X=X, y=y, sample_weight=sample_weight, **kwargs)\n",
      "  File \"/opt/anaconda3/envs/tf_env4/lib/python3.8/site-packages/scikeras/wrappers.py\", line 760, in fit\n",
      "    self._fit(\n",
      "  File \"/opt/anaconda3/envs/tf_env4/lib/python3.8/site-packages/scikeras/wrappers.py\", line 928, in _fit\n",
      "    self._fit_keras_model(\n",
      "  File \"/opt/anaconda3/envs/tf_env4/lib/python3.8/site-packages/scikeras/wrappers.py\", line 524, in _fit_keras_model\n",
      "    hist = self.model_.fit(x=X, y=y, **fit_args)\n",
      "  File \"/opt/anaconda3/envs/tf_env4/lib/python3.8/site-packages/keras/src/utils/traceback_utils.py\", line 70, in error_handler\n",
      "    raise e.with_traceback(filtered_tb) from None\n",
      "  File \"/var/folders/tz/9k5bcs_502z2svd2fr_k2w680000gn/T/__autograph_generated_file05s8fla1.py\", line 15, in tf__train_function\n",
      "    retval_ = ag__.converted_call(ag__.ld(step_function), (ag__.ld(self), ag__.ld(iterator)), None, fscope)\n",
      "ValueError: in user code:\n",
      "\n",
      "    File \"/opt/anaconda3/envs/tf_env4/lib/python3.8/site-packages/keras/src/engine/training.py\", line 1338, in train_function  *\n",
      "        return step_function(self, iterator)\n",
      "    File \"/opt/anaconda3/envs/tf_env4/lib/python3.8/site-packages/keras/src/engine/training.py\", line 1322, in step_function  **\n",
      "        outputs = model.distribute_strategy.run(run_step, args=(data,))\n",
      "    File \"/opt/anaconda3/envs/tf_env4/lib/python3.8/site-packages/keras/src/engine/training.py\", line 1303, in run_step  **\n",
      "        outputs = model.train_step(data)\n",
      "    File \"/opt/anaconda3/envs/tf_env4/lib/python3.8/site-packages/keras/src/engine/training.py\", line 1080, in train_step\n",
      "        y_pred = self(x, training=True)\n",
      "    File \"/opt/anaconda3/envs/tf_env4/lib/python3.8/site-packages/keras/src/utils/traceback_utils.py\", line 70, in error_handler\n",
      "        raise e.with_traceback(filtered_tb) from None\n",
      "\n",
      "    ValueError: Exception encountered when calling layer 'dropout_5' (type Dropout).\n",
      "    \n",
      "    `rate` must be a scalar or scalar tensor. Received: rate=None\n",
      "    \n",
      "    Call arguments received by layer 'dropout_5' (type Dropout):\n",
      "      • inputs=tf.Tensor(shape=(None, 25, 200), dtype=float32)\n",
      "      • training=True\n",
      "\n",
      "\n",
      "--------------------------------------------------------------------------------\n",
      "1 fits failed with the following error:\n",
      "Traceback (most recent call last):\n",
      "  File \"/opt/anaconda3/envs/tf_env4/lib/python3.8/site-packages/sklearn/model_selection/_validation.py\", line 729, in _fit_and_score\n",
      "    estimator.fit(X_train, y_train, **fit_params)\n",
      "  File \"/opt/anaconda3/envs/tf_env4/lib/python3.8/site-packages/scikeras/wrappers.py\", line 1491, in fit\n",
      "    super().fit(X=X, y=y, sample_weight=sample_weight, **kwargs)\n",
      "  File \"/opt/anaconda3/envs/tf_env4/lib/python3.8/site-packages/scikeras/wrappers.py\", line 760, in fit\n",
      "    self._fit(\n",
      "  File \"/opt/anaconda3/envs/tf_env4/lib/python3.8/site-packages/scikeras/wrappers.py\", line 928, in _fit\n",
      "    self._fit_keras_model(\n",
      "  File \"/opt/anaconda3/envs/tf_env4/lib/python3.8/site-packages/scikeras/wrappers.py\", line 524, in _fit_keras_model\n",
      "    hist = self.model_.fit(x=X, y=y, **fit_args)\n",
      "  File \"/opt/anaconda3/envs/tf_env4/lib/python3.8/site-packages/keras/src/utils/traceback_utils.py\", line 70, in error_handler\n",
      "    raise e.with_traceback(filtered_tb) from None\n",
      "  File \"/var/folders/tz/9k5bcs_502z2svd2fr_k2w680000gn/T/__autograph_generated_file05s8fla1.py\", line 15, in tf__train_function\n",
      "    retval_ = ag__.converted_call(ag__.ld(step_function), (ag__.ld(self), ag__.ld(iterator)), None, fscope)\n",
      "ValueError: in user code:\n",
      "\n",
      "    File \"/opt/anaconda3/envs/tf_env4/lib/python3.8/site-packages/keras/src/engine/training.py\", line 1338, in train_function  *\n",
      "        return step_function(self, iterator)\n",
      "    File \"/opt/anaconda3/envs/tf_env4/lib/python3.8/site-packages/keras/src/engine/training.py\", line 1322, in step_function  **\n",
      "        outputs = model.distribute_strategy.run(run_step, args=(data,))\n",
      "    File \"/opt/anaconda3/envs/tf_env4/lib/python3.8/site-packages/keras/src/engine/training.py\", line 1303, in run_step  **\n",
      "        outputs = model.train_step(data)\n",
      "    File \"/opt/anaconda3/envs/tf_env4/lib/python3.8/site-packages/keras/src/engine/training.py\", line 1080, in train_step\n",
      "        y_pred = self(x, training=True)\n",
      "    File \"/opt/anaconda3/envs/tf_env4/lib/python3.8/site-packages/keras/src/utils/traceback_utils.py\", line 70, in error_handler\n",
      "        raise e.with_traceback(filtered_tb) from None\n",
      "\n",
      "    ValueError: Exception encountered when calling layer 'dropout_6' (type Dropout).\n",
      "    \n",
      "    `rate` must be a scalar or scalar tensor. Received: rate=None\n",
      "    \n",
      "    Call arguments received by layer 'dropout_6' (type Dropout):\n",
      "      • inputs=tf.Tensor(shape=(None, 25, 200), dtype=float32)\n",
      "      • training=True\n",
      "\n",
      "\n",
      "--------------------------------------------------------------------------------\n",
      "1 fits failed with the following error:\n",
      "Traceback (most recent call last):\n",
      "  File \"/opt/anaconda3/envs/tf_env4/lib/python3.8/site-packages/sklearn/model_selection/_validation.py\", line 729, in _fit_and_score\n",
      "    estimator.fit(X_train, y_train, **fit_params)\n",
      "  File \"/opt/anaconda3/envs/tf_env4/lib/python3.8/site-packages/scikeras/wrappers.py\", line 1491, in fit\n",
      "    super().fit(X=X, y=y, sample_weight=sample_weight, **kwargs)\n",
      "  File \"/opt/anaconda3/envs/tf_env4/lib/python3.8/site-packages/scikeras/wrappers.py\", line 760, in fit\n",
      "    self._fit(\n",
      "  File \"/opt/anaconda3/envs/tf_env4/lib/python3.8/site-packages/scikeras/wrappers.py\", line 928, in _fit\n",
      "    self._fit_keras_model(\n",
      "  File \"/opt/anaconda3/envs/tf_env4/lib/python3.8/site-packages/scikeras/wrappers.py\", line 524, in _fit_keras_model\n",
      "    hist = self.model_.fit(x=X, y=y, **fit_args)\n",
      "  File \"/opt/anaconda3/envs/tf_env4/lib/python3.8/site-packages/keras/src/utils/traceback_utils.py\", line 70, in error_handler\n",
      "    raise e.with_traceback(filtered_tb) from None\n",
      "  File \"/var/folders/tz/9k5bcs_502z2svd2fr_k2w680000gn/T/__autograph_generated_file05s8fla1.py\", line 15, in tf__train_function\n",
      "    retval_ = ag__.converted_call(ag__.ld(step_function), (ag__.ld(self), ag__.ld(iterator)), None, fscope)\n",
      "ValueError: in user code:\n",
      "\n",
      "    File \"/opt/anaconda3/envs/tf_env4/lib/python3.8/site-packages/keras/src/engine/training.py\", line 1338, in train_function  *\n",
      "        return step_function(self, iterator)\n",
      "    File \"/opt/anaconda3/envs/tf_env4/lib/python3.8/site-packages/keras/src/engine/training.py\", line 1322, in step_function  **\n",
      "        outputs = model.distribute_strategy.run(run_step, args=(data,))\n",
      "    File \"/opt/anaconda3/envs/tf_env4/lib/python3.8/site-packages/keras/src/engine/training.py\", line 1303, in run_step  **\n",
      "        outputs = model.train_step(data)\n",
      "    File \"/opt/anaconda3/envs/tf_env4/lib/python3.8/site-packages/keras/src/engine/training.py\", line 1080, in train_step\n",
      "        y_pred = self(x, training=True)\n",
      "    File \"/opt/anaconda3/envs/tf_env4/lib/python3.8/site-packages/keras/src/utils/traceback_utils.py\", line 70, in error_handler\n",
      "        raise e.with_traceback(filtered_tb) from None\n",
      "\n",
      "    ValueError: Exception encountered when calling layer 'dropout_7' (type Dropout).\n",
      "    \n",
      "    `rate` must be a scalar or scalar tensor. Received: rate=None\n",
      "    \n",
      "    Call arguments received by layer 'dropout_7' (type Dropout):\n",
      "      • inputs=tf.Tensor(shape=(None, 25, 200), dtype=float32)\n",
      "      • training=True\n",
      "\n",
      "\n",
      "--------------------------------------------------------------------------------\n",
      "1 fits failed with the following error:\n",
      "Traceback (most recent call last):\n",
      "  File \"/opt/anaconda3/envs/tf_env4/lib/python3.8/site-packages/sklearn/model_selection/_validation.py\", line 729, in _fit_and_score\n",
      "    estimator.fit(X_train, y_train, **fit_params)\n",
      "  File \"/opt/anaconda3/envs/tf_env4/lib/python3.8/site-packages/scikeras/wrappers.py\", line 1491, in fit\n",
      "    super().fit(X=X, y=y, sample_weight=sample_weight, **kwargs)\n",
      "  File \"/opt/anaconda3/envs/tf_env4/lib/python3.8/site-packages/scikeras/wrappers.py\", line 760, in fit\n",
      "    self._fit(\n",
      "  File \"/opt/anaconda3/envs/tf_env4/lib/python3.8/site-packages/scikeras/wrappers.py\", line 928, in _fit\n",
      "    self._fit_keras_model(\n",
      "  File \"/opt/anaconda3/envs/tf_env4/lib/python3.8/site-packages/scikeras/wrappers.py\", line 524, in _fit_keras_model\n",
      "    hist = self.model_.fit(x=X, y=y, **fit_args)\n",
      "  File \"/opt/anaconda3/envs/tf_env4/lib/python3.8/site-packages/keras/src/utils/traceback_utils.py\", line 70, in error_handler\n",
      "    raise e.with_traceback(filtered_tb) from None\n",
      "  File \"/var/folders/tz/9k5bcs_502z2svd2fr_k2w680000gn/T/__autograph_generated_file05s8fla1.py\", line 15, in tf__train_function\n",
      "    retval_ = ag__.converted_call(ag__.ld(step_function), (ag__.ld(self), ag__.ld(iterator)), None, fscope)\n",
      "ValueError: in user code:\n",
      "\n",
      "    File \"/opt/anaconda3/envs/tf_env4/lib/python3.8/site-packages/keras/src/engine/training.py\", line 1338, in train_function  *\n",
      "        return step_function(self, iterator)\n",
      "    File \"/opt/anaconda3/envs/tf_env4/lib/python3.8/site-packages/keras/src/engine/training.py\", line 1322, in step_function  **\n",
      "        outputs = model.distribute_strategy.run(run_step, args=(data,))\n",
      "    File \"/opt/anaconda3/envs/tf_env4/lib/python3.8/site-packages/keras/src/engine/training.py\", line 1303, in run_step  **\n",
      "        outputs = model.train_step(data)\n",
      "    File \"/opt/anaconda3/envs/tf_env4/lib/python3.8/site-packages/keras/src/engine/training.py\", line 1080, in train_step\n",
      "        y_pred = self(x, training=True)\n",
      "    File \"/opt/anaconda3/envs/tf_env4/lib/python3.8/site-packages/keras/src/utils/traceback_utils.py\", line 70, in error_handler\n",
      "        raise e.with_traceback(filtered_tb) from None\n",
      "\n",
      "    ValueError: Exception encountered when calling layer 'dropout_8' (type Dropout).\n",
      "    \n",
      "    `rate` must be a scalar or scalar tensor. Received: rate=None\n",
      "    \n",
      "    Call arguments received by layer 'dropout_8' (type Dropout):\n",
      "      • inputs=tf.Tensor(shape=(None, 25, 200), dtype=float32)\n",
      "      • training=True\n",
      "\n",
      "\n",
      "--------------------------------------------------------------------------------\n",
      "1 fits failed with the following error:\n",
      "Traceback (most recent call last):\n",
      "  File \"/opt/anaconda3/envs/tf_env4/lib/python3.8/site-packages/sklearn/model_selection/_validation.py\", line 729, in _fit_and_score\n",
      "    estimator.fit(X_train, y_train, **fit_params)\n",
      "  File \"/opt/anaconda3/envs/tf_env4/lib/python3.8/site-packages/scikeras/wrappers.py\", line 1491, in fit\n",
      "    super().fit(X=X, y=y, sample_weight=sample_weight, **kwargs)\n",
      "  File \"/opt/anaconda3/envs/tf_env4/lib/python3.8/site-packages/scikeras/wrappers.py\", line 760, in fit\n",
      "    self._fit(\n",
      "  File \"/opt/anaconda3/envs/tf_env4/lib/python3.8/site-packages/scikeras/wrappers.py\", line 928, in _fit\n",
      "    self._fit_keras_model(\n",
      "  File \"/opt/anaconda3/envs/tf_env4/lib/python3.8/site-packages/scikeras/wrappers.py\", line 524, in _fit_keras_model\n",
      "    hist = self.model_.fit(x=X, y=y, **fit_args)\n",
      "  File \"/opt/anaconda3/envs/tf_env4/lib/python3.8/site-packages/keras/src/utils/traceback_utils.py\", line 70, in error_handler\n",
      "    raise e.with_traceback(filtered_tb) from None\n",
      "  File \"/var/folders/tz/9k5bcs_502z2svd2fr_k2w680000gn/T/__autograph_generated_file05s8fla1.py\", line 15, in tf__train_function\n",
      "    retval_ = ag__.converted_call(ag__.ld(step_function), (ag__.ld(self), ag__.ld(iterator)), None, fscope)\n",
      "ValueError: in user code:\n",
      "\n",
      "    File \"/opt/anaconda3/envs/tf_env4/lib/python3.8/site-packages/keras/src/engine/training.py\", line 1338, in train_function  *\n",
      "        return step_function(self, iterator)\n",
      "    File \"/opt/anaconda3/envs/tf_env4/lib/python3.8/site-packages/keras/src/engine/training.py\", line 1322, in step_function  **\n",
      "        outputs = model.distribute_strategy.run(run_step, args=(data,))\n",
      "    File \"/opt/anaconda3/envs/tf_env4/lib/python3.8/site-packages/keras/src/engine/training.py\", line 1303, in run_step  **\n",
      "        outputs = model.train_step(data)\n",
      "    File \"/opt/anaconda3/envs/tf_env4/lib/python3.8/site-packages/keras/src/engine/training.py\", line 1080, in train_step\n",
      "        y_pred = self(x, training=True)\n",
      "    File \"/opt/anaconda3/envs/tf_env4/lib/python3.8/site-packages/keras/src/utils/traceback_utils.py\", line 70, in error_handler\n",
      "        raise e.with_traceback(filtered_tb) from None\n",
      "\n",
      "    ValueError: Exception encountered when calling layer 'dropout_9' (type Dropout).\n",
      "    \n",
      "    `rate` must be a scalar or scalar tensor. Received: rate=None\n",
      "    \n",
      "    Call arguments received by layer 'dropout_9' (type Dropout):\n",
      "      • inputs=tf.Tensor(shape=(None, 25, 200), dtype=float32)\n",
      "      • training=True\n",
      "\n",
      "\n",
      "--------------------------------------------------------------------------------\n",
      "1 fits failed with the following error:\n",
      "Traceback (most recent call last):\n",
      "  File \"/opt/anaconda3/envs/tf_env4/lib/python3.8/site-packages/sklearn/model_selection/_validation.py\", line 729, in _fit_and_score\n",
      "    estimator.fit(X_train, y_train, **fit_params)\n",
      "  File \"/opt/anaconda3/envs/tf_env4/lib/python3.8/site-packages/scikeras/wrappers.py\", line 1491, in fit\n",
      "    super().fit(X=X, y=y, sample_weight=sample_weight, **kwargs)\n",
      "  File \"/opt/anaconda3/envs/tf_env4/lib/python3.8/site-packages/scikeras/wrappers.py\", line 760, in fit\n",
      "    self._fit(\n",
      "  File \"/opt/anaconda3/envs/tf_env4/lib/python3.8/site-packages/scikeras/wrappers.py\", line 928, in _fit\n",
      "    self._fit_keras_model(\n",
      "  File \"/opt/anaconda3/envs/tf_env4/lib/python3.8/site-packages/scikeras/wrappers.py\", line 524, in _fit_keras_model\n",
      "    hist = self.model_.fit(x=X, y=y, **fit_args)\n",
      "  File \"/opt/anaconda3/envs/tf_env4/lib/python3.8/site-packages/keras/src/utils/traceback_utils.py\", line 70, in error_handler\n",
      "    raise e.with_traceback(filtered_tb) from None\n",
      "  File \"/var/folders/tz/9k5bcs_502z2svd2fr_k2w680000gn/T/__autograph_generated_file05s8fla1.py\", line 15, in tf__train_function\n",
      "    retval_ = ag__.converted_call(ag__.ld(step_function), (ag__.ld(self), ag__.ld(iterator)), None, fscope)\n",
      "ValueError: in user code:\n",
      "\n",
      "    File \"/opt/anaconda3/envs/tf_env4/lib/python3.8/site-packages/keras/src/engine/training.py\", line 1338, in train_function  *\n",
      "        return step_function(self, iterator)\n",
      "    File \"/opt/anaconda3/envs/tf_env4/lib/python3.8/site-packages/keras/src/engine/training.py\", line 1322, in step_function  **\n",
      "        outputs = model.distribute_strategy.run(run_step, args=(data,))\n",
      "    File \"/opt/anaconda3/envs/tf_env4/lib/python3.8/site-packages/keras/src/engine/training.py\", line 1303, in run_step  **\n",
      "        outputs = model.train_step(data)\n",
      "    File \"/opt/anaconda3/envs/tf_env4/lib/python3.8/site-packages/keras/src/engine/training.py\", line 1080, in train_step\n",
      "        y_pred = self(x, training=True)\n",
      "    File \"/opt/anaconda3/envs/tf_env4/lib/python3.8/site-packages/keras/src/utils/traceback_utils.py\", line 70, in error_handler\n",
      "        raise e.with_traceback(filtered_tb) from None\n",
      "\n",
      "    ValueError: Exception encountered when calling layer 'dropout_15' (type Dropout).\n",
      "    \n",
      "    `rate` must be a scalar or scalar tensor. Received: rate=None\n",
      "    \n",
      "    Call arguments received by layer 'dropout_15' (type Dropout):\n",
      "      • inputs=tf.Tensor(shape=(None, 25, 200), dtype=float32)\n",
      "      • training=True\n",
      "\n",
      "\n",
      "--------------------------------------------------------------------------------\n",
      "1 fits failed with the following error:\n",
      "Traceback (most recent call last):\n",
      "  File \"/opt/anaconda3/envs/tf_env4/lib/python3.8/site-packages/sklearn/model_selection/_validation.py\", line 729, in _fit_and_score\n",
      "    estimator.fit(X_train, y_train, **fit_params)\n",
      "  File \"/opt/anaconda3/envs/tf_env4/lib/python3.8/site-packages/scikeras/wrappers.py\", line 1491, in fit\n",
      "    super().fit(X=X, y=y, sample_weight=sample_weight, **kwargs)\n",
      "  File \"/opt/anaconda3/envs/tf_env4/lib/python3.8/site-packages/scikeras/wrappers.py\", line 760, in fit\n",
      "    self._fit(\n",
      "  File \"/opt/anaconda3/envs/tf_env4/lib/python3.8/site-packages/scikeras/wrappers.py\", line 928, in _fit\n",
      "    self._fit_keras_model(\n",
      "  File \"/opt/anaconda3/envs/tf_env4/lib/python3.8/site-packages/scikeras/wrappers.py\", line 524, in _fit_keras_model\n",
      "    hist = self.model_.fit(x=X, y=y, **fit_args)\n",
      "  File \"/opt/anaconda3/envs/tf_env4/lib/python3.8/site-packages/keras/src/utils/traceback_utils.py\", line 70, in error_handler\n",
      "    raise e.with_traceback(filtered_tb) from None\n",
      "  File \"/var/folders/tz/9k5bcs_502z2svd2fr_k2w680000gn/T/__autograph_generated_file05s8fla1.py\", line 15, in tf__train_function\n",
      "    retval_ = ag__.converted_call(ag__.ld(step_function), (ag__.ld(self), ag__.ld(iterator)), None, fscope)\n",
      "ValueError: in user code:\n",
      "\n",
      "    File \"/opt/anaconda3/envs/tf_env4/lib/python3.8/site-packages/keras/src/engine/training.py\", line 1338, in train_function  *\n",
      "        return step_function(self, iterator)\n",
      "    File \"/opt/anaconda3/envs/tf_env4/lib/python3.8/site-packages/keras/src/engine/training.py\", line 1322, in step_function  **\n",
      "        outputs = model.distribute_strategy.run(run_step, args=(data,))\n",
      "    File \"/opt/anaconda3/envs/tf_env4/lib/python3.8/site-packages/keras/src/engine/training.py\", line 1303, in run_step  **\n",
      "        outputs = model.train_step(data)\n",
      "    File \"/opt/anaconda3/envs/tf_env4/lib/python3.8/site-packages/keras/src/engine/training.py\", line 1080, in train_step\n",
      "        y_pred = self(x, training=True)\n",
      "    File \"/opt/anaconda3/envs/tf_env4/lib/python3.8/site-packages/keras/src/utils/traceback_utils.py\", line 70, in error_handler\n",
      "        raise e.with_traceback(filtered_tb) from None\n",
      "\n",
      "    ValueError: Exception encountered when calling layer 'dropout_16' (type Dropout).\n",
      "    \n",
      "    `rate` must be a scalar or scalar tensor. Received: rate=None\n",
      "    \n",
      "    Call arguments received by layer 'dropout_16' (type Dropout):\n",
      "      • inputs=tf.Tensor(shape=(None, 25, 200), dtype=float32)\n",
      "      • training=True\n",
      "\n",
      "\n",
      "--------------------------------------------------------------------------------\n",
      "1 fits failed with the following error:\n",
      "Traceback (most recent call last):\n",
      "  File \"/opt/anaconda3/envs/tf_env4/lib/python3.8/site-packages/sklearn/model_selection/_validation.py\", line 729, in _fit_and_score\n",
      "    estimator.fit(X_train, y_train, **fit_params)\n",
      "  File \"/opt/anaconda3/envs/tf_env4/lib/python3.8/site-packages/scikeras/wrappers.py\", line 1491, in fit\n",
      "    super().fit(X=X, y=y, sample_weight=sample_weight, **kwargs)\n",
      "  File \"/opt/anaconda3/envs/tf_env4/lib/python3.8/site-packages/scikeras/wrappers.py\", line 760, in fit\n",
      "    self._fit(\n",
      "  File \"/opt/anaconda3/envs/tf_env4/lib/python3.8/site-packages/scikeras/wrappers.py\", line 928, in _fit\n",
      "    self._fit_keras_model(\n",
      "  File \"/opt/anaconda3/envs/tf_env4/lib/python3.8/site-packages/scikeras/wrappers.py\", line 524, in _fit_keras_model\n",
      "    hist = self.model_.fit(x=X, y=y, **fit_args)\n",
      "  File \"/opt/anaconda3/envs/tf_env4/lib/python3.8/site-packages/keras/src/utils/traceback_utils.py\", line 70, in error_handler\n",
      "    raise e.with_traceback(filtered_tb) from None\n",
      "  File \"/var/folders/tz/9k5bcs_502z2svd2fr_k2w680000gn/T/__autograph_generated_file05s8fla1.py\", line 15, in tf__train_function\n",
      "    retval_ = ag__.converted_call(ag__.ld(step_function), (ag__.ld(self), ag__.ld(iterator)), None, fscope)\n",
      "ValueError: in user code:\n",
      "\n",
      "    File \"/opt/anaconda3/envs/tf_env4/lib/python3.8/site-packages/keras/src/engine/training.py\", line 1338, in train_function  *\n",
      "        return step_function(self, iterator)\n",
      "    File \"/opt/anaconda3/envs/tf_env4/lib/python3.8/site-packages/keras/src/engine/training.py\", line 1322, in step_function  **\n",
      "        outputs = model.distribute_strategy.run(run_step, args=(data,))\n",
      "    File \"/opt/anaconda3/envs/tf_env4/lib/python3.8/site-packages/keras/src/engine/training.py\", line 1303, in run_step  **\n",
      "        outputs = model.train_step(data)\n",
      "    File \"/opt/anaconda3/envs/tf_env4/lib/python3.8/site-packages/keras/src/engine/training.py\", line 1080, in train_step\n",
      "        y_pred = self(x, training=True)\n",
      "    File \"/opt/anaconda3/envs/tf_env4/lib/python3.8/site-packages/keras/src/utils/traceback_utils.py\", line 70, in error_handler\n",
      "        raise e.with_traceback(filtered_tb) from None\n",
      "\n",
      "    ValueError: Exception encountered when calling layer 'dropout_17' (type Dropout).\n",
      "    \n",
      "    `rate` must be a scalar or scalar tensor. Received: rate=None\n",
      "    \n",
      "    Call arguments received by layer 'dropout_17' (type Dropout):\n",
      "      • inputs=tf.Tensor(shape=(None, 25, 200), dtype=float32)\n",
      "      • training=True\n",
      "\n",
      "\n",
      "--------------------------------------------------------------------------------\n",
      "1 fits failed with the following error:\n",
      "Traceback (most recent call last):\n",
      "  File \"/opt/anaconda3/envs/tf_env4/lib/python3.8/site-packages/sklearn/model_selection/_validation.py\", line 729, in _fit_and_score\n",
      "    estimator.fit(X_train, y_train, **fit_params)\n",
      "  File \"/opt/anaconda3/envs/tf_env4/lib/python3.8/site-packages/scikeras/wrappers.py\", line 1491, in fit\n",
      "    super().fit(X=X, y=y, sample_weight=sample_weight, **kwargs)\n",
      "  File \"/opt/anaconda3/envs/tf_env4/lib/python3.8/site-packages/scikeras/wrappers.py\", line 760, in fit\n",
      "    self._fit(\n",
      "  File \"/opt/anaconda3/envs/tf_env4/lib/python3.8/site-packages/scikeras/wrappers.py\", line 928, in _fit\n",
      "    self._fit_keras_model(\n",
      "  File \"/opt/anaconda3/envs/tf_env4/lib/python3.8/site-packages/scikeras/wrappers.py\", line 524, in _fit_keras_model\n",
      "    hist = self.model_.fit(x=X, y=y, **fit_args)\n",
      "  File \"/opt/anaconda3/envs/tf_env4/lib/python3.8/site-packages/keras/src/utils/traceback_utils.py\", line 70, in error_handler\n",
      "    raise e.with_traceback(filtered_tb) from None\n",
      "  File \"/var/folders/tz/9k5bcs_502z2svd2fr_k2w680000gn/T/__autograph_generated_file05s8fla1.py\", line 15, in tf__train_function\n",
      "    retval_ = ag__.converted_call(ag__.ld(step_function), (ag__.ld(self), ag__.ld(iterator)), None, fscope)\n",
      "ValueError: in user code:\n",
      "\n",
      "    File \"/opt/anaconda3/envs/tf_env4/lib/python3.8/site-packages/keras/src/engine/training.py\", line 1338, in train_function  *\n",
      "        return step_function(self, iterator)\n",
      "    File \"/opt/anaconda3/envs/tf_env4/lib/python3.8/site-packages/keras/src/engine/training.py\", line 1322, in step_function  **\n",
      "        outputs = model.distribute_strategy.run(run_step, args=(data,))\n",
      "    File \"/opt/anaconda3/envs/tf_env4/lib/python3.8/site-packages/keras/src/engine/training.py\", line 1303, in run_step  **\n",
      "        outputs = model.train_step(data)\n",
      "    File \"/opt/anaconda3/envs/tf_env4/lib/python3.8/site-packages/keras/src/engine/training.py\", line 1080, in train_step\n",
      "        y_pred = self(x, training=True)\n",
      "    File \"/opt/anaconda3/envs/tf_env4/lib/python3.8/site-packages/keras/src/utils/traceback_utils.py\", line 70, in error_handler\n",
      "        raise e.with_traceback(filtered_tb) from None\n",
      "\n",
      "    ValueError: Exception encountered when calling layer 'dropout_18' (type Dropout).\n",
      "    \n",
      "    `rate` must be a scalar or scalar tensor. Received: rate=None\n",
      "    \n",
      "    Call arguments received by layer 'dropout_18' (type Dropout):\n",
      "      • inputs=tf.Tensor(shape=(None, 25, 200), dtype=float32)\n",
      "      • training=True\n",
      "\n",
      "\n",
      "--------------------------------------------------------------------------------\n",
      "1 fits failed with the following error:\n",
      "Traceback (most recent call last):\n",
      "  File \"/opt/anaconda3/envs/tf_env4/lib/python3.8/site-packages/sklearn/model_selection/_validation.py\", line 729, in _fit_and_score\n",
      "    estimator.fit(X_train, y_train, **fit_params)\n",
      "  File \"/opt/anaconda3/envs/tf_env4/lib/python3.8/site-packages/scikeras/wrappers.py\", line 1491, in fit\n",
      "    super().fit(X=X, y=y, sample_weight=sample_weight, **kwargs)\n",
      "  File \"/opt/anaconda3/envs/tf_env4/lib/python3.8/site-packages/scikeras/wrappers.py\", line 760, in fit\n",
      "    self._fit(\n",
      "  File \"/opt/anaconda3/envs/tf_env4/lib/python3.8/site-packages/scikeras/wrappers.py\", line 928, in _fit\n",
      "    self._fit_keras_model(\n",
      "  File \"/opt/anaconda3/envs/tf_env4/lib/python3.8/site-packages/scikeras/wrappers.py\", line 524, in _fit_keras_model\n",
      "    hist = self.model_.fit(x=X, y=y, **fit_args)\n",
      "  File \"/opt/anaconda3/envs/tf_env4/lib/python3.8/site-packages/keras/src/utils/traceback_utils.py\", line 70, in error_handler\n",
      "    raise e.with_traceback(filtered_tb) from None\n",
      "  File \"/var/folders/tz/9k5bcs_502z2svd2fr_k2w680000gn/T/__autograph_generated_file05s8fla1.py\", line 15, in tf__train_function\n",
      "    retval_ = ag__.converted_call(ag__.ld(step_function), (ag__.ld(self), ag__.ld(iterator)), None, fscope)\n",
      "ValueError: in user code:\n",
      "\n",
      "    File \"/opt/anaconda3/envs/tf_env4/lib/python3.8/site-packages/keras/src/engine/training.py\", line 1338, in train_function  *\n",
      "        return step_function(self, iterator)\n",
      "    File \"/opt/anaconda3/envs/tf_env4/lib/python3.8/site-packages/keras/src/engine/training.py\", line 1322, in step_function  **\n",
      "        outputs = model.distribute_strategy.run(run_step, args=(data,))\n",
      "    File \"/opt/anaconda3/envs/tf_env4/lib/python3.8/site-packages/keras/src/engine/training.py\", line 1303, in run_step  **\n",
      "        outputs = model.train_step(data)\n",
      "    File \"/opt/anaconda3/envs/tf_env4/lib/python3.8/site-packages/keras/src/engine/training.py\", line 1080, in train_step\n",
      "        y_pred = self(x, training=True)\n",
      "    File \"/opt/anaconda3/envs/tf_env4/lib/python3.8/site-packages/keras/src/utils/traceback_utils.py\", line 70, in error_handler\n",
      "        raise e.with_traceback(filtered_tb) from None\n",
      "\n",
      "    ValueError: Exception encountered when calling layer 'dropout_19' (type Dropout).\n",
      "    \n",
      "    `rate` must be a scalar or scalar tensor. Received: rate=None\n",
      "    \n",
      "    Call arguments received by layer 'dropout_19' (type Dropout):\n",
      "      • inputs=tf.Tensor(shape=(None, 25, 200), dtype=float32)\n",
      "      • training=True\n",
      "\n",
      "\n",
      "--------------------------------------------------------------------------------\n",
      "1 fits failed with the following error:\n",
      "Traceback (most recent call last):\n",
      "  File \"/opt/anaconda3/envs/tf_env4/lib/python3.8/site-packages/sklearn/model_selection/_validation.py\", line 729, in _fit_and_score\n",
      "    estimator.fit(X_train, y_train, **fit_params)\n",
      "  File \"/opt/anaconda3/envs/tf_env4/lib/python3.8/site-packages/scikeras/wrappers.py\", line 1491, in fit\n",
      "    super().fit(X=X, y=y, sample_weight=sample_weight, **kwargs)\n",
      "  File \"/opt/anaconda3/envs/tf_env4/lib/python3.8/site-packages/scikeras/wrappers.py\", line 760, in fit\n",
      "    self._fit(\n",
      "  File \"/opt/anaconda3/envs/tf_env4/lib/python3.8/site-packages/scikeras/wrappers.py\", line 928, in _fit\n",
      "    self._fit_keras_model(\n",
      "  File \"/opt/anaconda3/envs/tf_env4/lib/python3.8/site-packages/scikeras/wrappers.py\", line 524, in _fit_keras_model\n",
      "    hist = self.model_.fit(x=X, y=y, **fit_args)\n",
      "  File \"/opt/anaconda3/envs/tf_env4/lib/python3.8/site-packages/keras/src/utils/traceback_utils.py\", line 70, in error_handler\n",
      "    raise e.with_traceback(filtered_tb) from None\n",
      "  File \"/var/folders/tz/9k5bcs_502z2svd2fr_k2w680000gn/T/__autograph_generated_file05s8fla1.py\", line 15, in tf__train_function\n",
      "    retval_ = ag__.converted_call(ag__.ld(step_function), (ag__.ld(self), ag__.ld(iterator)), None, fscope)\n",
      "ValueError: in user code:\n",
      "\n",
      "    File \"/opt/anaconda3/envs/tf_env4/lib/python3.8/site-packages/keras/src/engine/training.py\", line 1338, in train_function  *\n",
      "        return step_function(self, iterator)\n",
      "    File \"/opt/anaconda3/envs/tf_env4/lib/python3.8/site-packages/keras/src/engine/training.py\", line 1322, in step_function  **\n",
      "        outputs = model.distribute_strategy.run(run_step, args=(data,))\n",
      "    File \"/opt/anaconda3/envs/tf_env4/lib/python3.8/site-packages/keras/src/engine/training.py\", line 1303, in run_step  **\n",
      "        outputs = model.train_step(data)\n",
      "    File \"/opt/anaconda3/envs/tf_env4/lib/python3.8/site-packages/keras/src/engine/training.py\", line 1080, in train_step\n",
      "        y_pred = self(x, training=True)\n",
      "    File \"/opt/anaconda3/envs/tf_env4/lib/python3.8/site-packages/keras/src/utils/traceback_utils.py\", line 70, in error_handler\n",
      "        raise e.with_traceback(filtered_tb) from None\n",
      "\n",
      "    ValueError: Exception encountered when calling layer 'dropout_35' (type Dropout).\n",
      "    \n",
      "    `rate` must be a scalar or scalar tensor. Received: rate=None\n",
      "    \n",
      "    Call arguments received by layer 'dropout_35' (type Dropout):\n",
      "      • inputs=tf.Tensor(shape=(None, 25, 200), dtype=float32)\n",
      "      • training=True\n",
      "\n",
      "\n",
      "--------------------------------------------------------------------------------\n",
      "1 fits failed with the following error:\n",
      "Traceback (most recent call last):\n",
      "  File \"/opt/anaconda3/envs/tf_env4/lib/python3.8/site-packages/sklearn/model_selection/_validation.py\", line 729, in _fit_and_score\n",
      "    estimator.fit(X_train, y_train, **fit_params)\n",
      "  File \"/opt/anaconda3/envs/tf_env4/lib/python3.8/site-packages/scikeras/wrappers.py\", line 1491, in fit\n",
      "    super().fit(X=X, y=y, sample_weight=sample_weight, **kwargs)\n",
      "  File \"/opt/anaconda3/envs/tf_env4/lib/python3.8/site-packages/scikeras/wrappers.py\", line 760, in fit\n",
      "    self._fit(\n",
      "  File \"/opt/anaconda3/envs/tf_env4/lib/python3.8/site-packages/scikeras/wrappers.py\", line 928, in _fit\n",
      "    self._fit_keras_model(\n",
      "  File \"/opt/anaconda3/envs/tf_env4/lib/python3.8/site-packages/scikeras/wrappers.py\", line 524, in _fit_keras_model\n",
      "    hist = self.model_.fit(x=X, y=y, **fit_args)\n",
      "  File \"/opt/anaconda3/envs/tf_env4/lib/python3.8/site-packages/keras/src/utils/traceback_utils.py\", line 70, in error_handler\n",
      "    raise e.with_traceback(filtered_tb) from None\n",
      "  File \"/var/folders/tz/9k5bcs_502z2svd2fr_k2w680000gn/T/__autograph_generated_file05s8fla1.py\", line 15, in tf__train_function\n",
      "    retval_ = ag__.converted_call(ag__.ld(step_function), (ag__.ld(self), ag__.ld(iterator)), None, fscope)\n",
      "ValueError: in user code:\n",
      "\n",
      "    File \"/opt/anaconda3/envs/tf_env4/lib/python3.8/site-packages/keras/src/engine/training.py\", line 1338, in train_function  *\n",
      "        return step_function(self, iterator)\n",
      "    File \"/opt/anaconda3/envs/tf_env4/lib/python3.8/site-packages/keras/src/engine/training.py\", line 1322, in step_function  **\n",
      "        outputs = model.distribute_strategy.run(run_step, args=(data,))\n",
      "    File \"/opt/anaconda3/envs/tf_env4/lib/python3.8/site-packages/keras/src/engine/training.py\", line 1303, in run_step  **\n",
      "        outputs = model.train_step(data)\n",
      "    File \"/opt/anaconda3/envs/tf_env4/lib/python3.8/site-packages/keras/src/engine/training.py\", line 1080, in train_step\n",
      "        y_pred = self(x, training=True)\n",
      "    File \"/opt/anaconda3/envs/tf_env4/lib/python3.8/site-packages/keras/src/utils/traceback_utils.py\", line 70, in error_handler\n",
      "        raise e.with_traceback(filtered_tb) from None\n",
      "\n",
      "    ValueError: Exception encountered when calling layer 'dropout_36' (type Dropout).\n",
      "    \n",
      "    `rate` must be a scalar or scalar tensor. Received: rate=None\n",
      "    \n",
      "    Call arguments received by layer 'dropout_36' (type Dropout):\n",
      "      • inputs=tf.Tensor(shape=(None, 25, 200), dtype=float32)\n",
      "      • training=True\n",
      "\n",
      "\n",
      "--------------------------------------------------------------------------------\n",
      "1 fits failed with the following error:\n",
      "Traceback (most recent call last):\n",
      "  File \"/opt/anaconda3/envs/tf_env4/lib/python3.8/site-packages/sklearn/model_selection/_validation.py\", line 729, in _fit_and_score\n",
      "    estimator.fit(X_train, y_train, **fit_params)\n",
      "  File \"/opt/anaconda3/envs/tf_env4/lib/python3.8/site-packages/scikeras/wrappers.py\", line 1491, in fit\n",
      "    super().fit(X=X, y=y, sample_weight=sample_weight, **kwargs)\n",
      "  File \"/opt/anaconda3/envs/tf_env4/lib/python3.8/site-packages/scikeras/wrappers.py\", line 760, in fit\n",
      "    self._fit(\n",
      "  File \"/opt/anaconda3/envs/tf_env4/lib/python3.8/site-packages/scikeras/wrappers.py\", line 928, in _fit\n",
      "    self._fit_keras_model(\n",
      "  File \"/opt/anaconda3/envs/tf_env4/lib/python3.8/site-packages/scikeras/wrappers.py\", line 524, in _fit_keras_model\n",
      "    hist = self.model_.fit(x=X, y=y, **fit_args)\n",
      "  File \"/opt/anaconda3/envs/tf_env4/lib/python3.8/site-packages/keras/src/utils/traceback_utils.py\", line 70, in error_handler\n",
      "    raise e.with_traceback(filtered_tb) from None\n",
      "  File \"/var/folders/tz/9k5bcs_502z2svd2fr_k2w680000gn/T/__autograph_generated_file05s8fla1.py\", line 15, in tf__train_function\n",
      "    retval_ = ag__.converted_call(ag__.ld(step_function), (ag__.ld(self), ag__.ld(iterator)), None, fscope)\n",
      "ValueError: in user code:\n",
      "\n",
      "    File \"/opt/anaconda3/envs/tf_env4/lib/python3.8/site-packages/keras/src/engine/training.py\", line 1338, in train_function  *\n",
      "        return step_function(self, iterator)\n",
      "    File \"/opt/anaconda3/envs/tf_env4/lib/python3.8/site-packages/keras/src/engine/training.py\", line 1322, in step_function  **\n",
      "        outputs = model.distribute_strategy.run(run_step, args=(data,))\n",
      "    File \"/opt/anaconda3/envs/tf_env4/lib/python3.8/site-packages/keras/src/engine/training.py\", line 1303, in run_step  **\n",
      "        outputs = model.train_step(data)\n",
      "    File \"/opt/anaconda3/envs/tf_env4/lib/python3.8/site-packages/keras/src/engine/training.py\", line 1080, in train_step\n",
      "        y_pred = self(x, training=True)\n",
      "    File \"/opt/anaconda3/envs/tf_env4/lib/python3.8/site-packages/keras/src/utils/traceback_utils.py\", line 70, in error_handler\n",
      "        raise e.with_traceback(filtered_tb) from None\n",
      "\n",
      "    ValueError: Exception encountered when calling layer 'dropout_37' (type Dropout).\n",
      "    \n",
      "    `rate` must be a scalar or scalar tensor. Received: rate=None\n",
      "    \n",
      "    Call arguments received by layer 'dropout_37' (type Dropout):\n",
      "      • inputs=tf.Tensor(shape=(None, 25, 200), dtype=float32)\n",
      "      • training=True\n",
      "\n",
      "\n",
      "--------------------------------------------------------------------------------\n",
      "1 fits failed with the following error:\n",
      "Traceback (most recent call last):\n",
      "  File \"/opt/anaconda3/envs/tf_env4/lib/python3.8/site-packages/sklearn/model_selection/_validation.py\", line 729, in _fit_and_score\n",
      "    estimator.fit(X_train, y_train, **fit_params)\n",
      "  File \"/opt/anaconda3/envs/tf_env4/lib/python3.8/site-packages/scikeras/wrappers.py\", line 1491, in fit\n",
      "    super().fit(X=X, y=y, sample_weight=sample_weight, **kwargs)\n",
      "  File \"/opt/anaconda3/envs/tf_env4/lib/python3.8/site-packages/scikeras/wrappers.py\", line 760, in fit\n",
      "    self._fit(\n",
      "  File \"/opt/anaconda3/envs/tf_env4/lib/python3.8/site-packages/scikeras/wrappers.py\", line 928, in _fit\n",
      "    self._fit_keras_model(\n",
      "  File \"/opt/anaconda3/envs/tf_env4/lib/python3.8/site-packages/scikeras/wrappers.py\", line 524, in _fit_keras_model\n",
      "    hist = self.model_.fit(x=X, y=y, **fit_args)\n",
      "  File \"/opt/anaconda3/envs/tf_env4/lib/python3.8/site-packages/keras/src/utils/traceback_utils.py\", line 70, in error_handler\n",
      "    raise e.with_traceback(filtered_tb) from None\n",
      "  File \"/var/folders/tz/9k5bcs_502z2svd2fr_k2w680000gn/T/__autograph_generated_file05s8fla1.py\", line 15, in tf__train_function\n",
      "    retval_ = ag__.converted_call(ag__.ld(step_function), (ag__.ld(self), ag__.ld(iterator)), None, fscope)\n",
      "ValueError: in user code:\n",
      "\n",
      "    File \"/opt/anaconda3/envs/tf_env4/lib/python3.8/site-packages/keras/src/engine/training.py\", line 1338, in train_function  *\n",
      "        return step_function(self, iterator)\n",
      "    File \"/opt/anaconda3/envs/tf_env4/lib/python3.8/site-packages/keras/src/engine/training.py\", line 1322, in step_function  **\n",
      "        outputs = model.distribute_strategy.run(run_step, args=(data,))\n",
      "    File \"/opt/anaconda3/envs/tf_env4/lib/python3.8/site-packages/keras/src/engine/training.py\", line 1303, in run_step  **\n",
      "        outputs = model.train_step(data)\n",
      "    File \"/opt/anaconda3/envs/tf_env4/lib/python3.8/site-packages/keras/src/engine/training.py\", line 1080, in train_step\n",
      "        y_pred = self(x, training=True)\n",
      "    File \"/opt/anaconda3/envs/tf_env4/lib/python3.8/site-packages/keras/src/utils/traceback_utils.py\", line 70, in error_handler\n",
      "        raise e.with_traceback(filtered_tb) from None\n",
      "\n",
      "    ValueError: Exception encountered when calling layer 'dropout_38' (type Dropout).\n",
      "    \n",
      "    `rate` must be a scalar or scalar tensor. Received: rate=None\n",
      "    \n",
      "    Call arguments received by layer 'dropout_38' (type Dropout):\n",
      "      • inputs=tf.Tensor(shape=(None, 25, 200), dtype=float32)\n",
      "      • training=True\n",
      "\n",
      "\n",
      "--------------------------------------------------------------------------------\n",
      "1 fits failed with the following error:\n",
      "Traceback (most recent call last):\n",
      "  File \"/opt/anaconda3/envs/tf_env4/lib/python3.8/site-packages/sklearn/model_selection/_validation.py\", line 729, in _fit_and_score\n",
      "    estimator.fit(X_train, y_train, **fit_params)\n",
      "  File \"/opt/anaconda3/envs/tf_env4/lib/python3.8/site-packages/scikeras/wrappers.py\", line 1491, in fit\n",
      "    super().fit(X=X, y=y, sample_weight=sample_weight, **kwargs)\n",
      "  File \"/opt/anaconda3/envs/tf_env4/lib/python3.8/site-packages/scikeras/wrappers.py\", line 760, in fit\n",
      "    self._fit(\n",
      "  File \"/opt/anaconda3/envs/tf_env4/lib/python3.8/site-packages/scikeras/wrappers.py\", line 928, in _fit\n",
      "    self._fit_keras_model(\n",
      "  File \"/opt/anaconda3/envs/tf_env4/lib/python3.8/site-packages/scikeras/wrappers.py\", line 524, in _fit_keras_model\n",
      "    hist = self.model_.fit(x=X, y=y, **fit_args)\n",
      "  File \"/opt/anaconda3/envs/tf_env4/lib/python3.8/site-packages/keras/src/utils/traceback_utils.py\", line 70, in error_handler\n",
      "    raise e.with_traceback(filtered_tb) from None\n",
      "  File \"/var/folders/tz/9k5bcs_502z2svd2fr_k2w680000gn/T/__autograph_generated_file05s8fla1.py\", line 15, in tf__train_function\n",
      "    retval_ = ag__.converted_call(ag__.ld(step_function), (ag__.ld(self), ag__.ld(iterator)), None, fscope)\n",
      "ValueError: in user code:\n",
      "\n",
      "    File \"/opt/anaconda3/envs/tf_env4/lib/python3.8/site-packages/keras/src/engine/training.py\", line 1338, in train_function  *\n",
      "        return step_function(self, iterator)\n",
      "    File \"/opt/anaconda3/envs/tf_env4/lib/python3.8/site-packages/keras/src/engine/training.py\", line 1322, in step_function  **\n",
      "        outputs = model.distribute_strategy.run(run_step, args=(data,))\n",
      "    File \"/opt/anaconda3/envs/tf_env4/lib/python3.8/site-packages/keras/src/engine/training.py\", line 1303, in run_step  **\n",
      "        outputs = model.train_step(data)\n",
      "    File \"/opt/anaconda3/envs/tf_env4/lib/python3.8/site-packages/keras/src/engine/training.py\", line 1080, in train_step\n",
      "        y_pred = self(x, training=True)\n",
      "    File \"/opt/anaconda3/envs/tf_env4/lib/python3.8/site-packages/keras/src/utils/traceback_utils.py\", line 70, in error_handler\n",
      "        raise e.with_traceback(filtered_tb) from None\n",
      "\n",
      "    ValueError: Exception encountered when calling layer 'dropout_39' (type Dropout).\n",
      "    \n",
      "    `rate` must be a scalar or scalar tensor. Received: rate=None\n",
      "    \n",
      "    Call arguments received by layer 'dropout_39' (type Dropout):\n",
      "      • inputs=tf.Tensor(shape=(None, 25, 200), dtype=float32)\n",
      "      • training=True\n",
      "\n",
      "\n",
      "  warnings.warn(some_fits_failed_message, FitFailedWarning)\n",
      "/opt/anaconda3/envs/tf_env4/lib/python3.8/site-packages/sklearn/model_selection/_search.py:979: UserWarning: One or more of the test scores are non-finite: [       nan        nan 0.92009644        nan 0.92644589 0.91456117\n",
      " 0.92725974        nan 0.92771566 0.9248502 ]\n",
      "  warnings.warn(\n"
     ]
    },
    {
     "name": "stdout",
     "output_type": "stream",
     "text": [
      "Epoch 1/5\n",
      "384/384 [==============================] - 24s 59ms/step - loss: 0.3599 - acc: 0.8737 - val_loss: 0.2494 - val_acc: 0.9105\n",
      "Epoch 2/5\n",
      "384/384 [==============================] - 24s 62ms/step - loss: 0.2317 - acc: 0.9190 - val_loss: 0.2236 - val_acc: 0.9224\n",
      "Epoch 3/5\n",
      "384/384 [==============================] - 22s 59ms/step - loss: 0.1948 - acc: 0.9303 - val_loss: 0.2024 - val_acc: 0.9264\n",
      "Epoch 4/5\n",
      "384/384 [==============================] - 24s 61ms/step - loss: 0.1708 - acc: 0.9384 - val_loss: 0.1918 - val_acc: 0.9298\n",
      "Epoch 5/5\n",
      "384/384 [==============================] - 22s 58ms/step - loss: 0.1484 - acc: 0.9464 - val_loss: 0.1948 - val_acc: 0.9307\n"
     ]
    }
   ],
   "source": [
    "#import warnings\n",
    "#warnings.filterwarnings(\"ignore\")\n",
    "\n",
    "\n",
    "model = KerasClassifier(model=create_lstm_model, units=256, batch_size=64, dropout=0.2, validation_split=0.2,optimizer__learning_rate=0.1, vocab_length=vocab_length, embedding_matrix=embedding_matrix, max_len=max_len)\n",
    "\n",
    "# Define the grid search parameters\n",
    "param_grid = dict(optimizer__learning_rate=[0.001,0.01,0.1],\n",
    "                dropout=[None, 0.1, 0.2, 0.3, 0.5],epochs=[5, 10],\n",
    "                units=[32,64,128,256],batch_size=[32, 64, 128,256])\n",
    "\n",
    "# Perform grid search\n",
    "grid = RandomizedSearchCV(estimator=model, param_distributions=param_grid,refit=True,cv=5)\n",
    "grid_result = grid.fit(X_train, y_train)"
   ]
  },
  {
   "cell_type": "code",
   "execution_count": 10,
   "metadata": {},
   "outputs": [
    {
     "name": "stdout",
     "output_type": "stream",
     "text": [
      "Best: 0.927716 using {'units': 256, 'optimizer__learning_rate': 0.1, 'epochs': 5, 'dropout': 0.2, 'batch_size': 64}\n",
      "nan (nan) with: {'units': 64, 'optimizer__learning_rate': 0.1, 'epochs': 10, 'dropout': None, 'batch_size': 256}\n",
      "nan (nan) with: {'units': 256, 'optimizer__learning_rate': 0.1, 'epochs': 10, 'dropout': None, 'batch_size': 128}\n",
      "0.920096 (0.003263) with: {'units': 32, 'optimizer__learning_rate': 0.001, 'epochs': 5, 'dropout': 0.3, 'batch_size': 128}\n",
      "nan (nan) with: {'units': 32, 'optimizer__learning_rate': 0.001, 'epochs': 10, 'dropout': None, 'batch_size': 256}\n",
      "0.926446 (0.004566) with: {'units': 256, 'optimizer__learning_rate': 0.001, 'epochs': 10, 'dropout': 0.3, 'batch_size': 256}\n",
      "0.914561 (0.002471) with: {'units': 32, 'optimizer__learning_rate': 0.01, 'epochs': 5, 'dropout': 0.3, 'batch_size': 256}\n",
      "0.927260 (0.003443) with: {'units': 64, 'optimizer__learning_rate': 0.1, 'epochs': 10, 'dropout': 0.2, 'batch_size': 128}\n",
      "nan (nan) with: {'units': 64, 'optimizer__learning_rate': 0.01, 'epochs': 5, 'dropout': None, 'batch_size': 256}\n",
      "0.927716 (0.002735) with: {'units': 256, 'optimizer__learning_rate': 0.1, 'epochs': 5, 'dropout': 0.2, 'batch_size': 64}\n",
      "0.924850 (0.003567) with: {'units': 128, 'optimizer__learning_rate': 0.001, 'epochs': 10, 'dropout': 0.1, 'batch_size': 32}\n"
     ]
    }
   ],
   "source": [
    "# Summarize results\n",
    "print(\"Best: %f using %s\" % (grid_result.best_score_, grid_result.best_params_))\n",
    "means = grid_result.cv_results_['mean_test_score']\n",
    "stds = grid_result.cv_results_['std_test_score']\n",
    "params = grid_result.cv_results_['params']\n",
    "for mean, stdev, param in zip(means, stds, params):\n",
    "    print(\"%f (%f) with: %r\" % (mean, stdev, param))"
   ]
  },
  {
   "cell_type": "code",
   "execution_count": null,
   "metadata": {},
   "outputs": [
    {
     "ename": "NameError",
     "evalue": "name 'lstm_model_history' is not defined",
     "output_type": "error",
     "traceback": [
      "\u001b[0;31m---------------------------------------------------------------------------\u001b[0m",
      "\u001b[0;31mNameError\u001b[0m                                 Traceback (most recent call last)",
      "Cell \u001b[0;32mIn[21], line 4\u001b[0m\n\u001b[1;32m      1\u001b[0m \u001b[39mimport\u001b[39;00m \u001b[39mmatplotlib\u001b[39;00m\u001b[39m.\u001b[39;00m\u001b[39mpyplot\u001b[39;00m \u001b[39mas\u001b[39;00m \u001b[39mplt\u001b[39;00m\n\u001b[1;32m      3\u001b[0m \u001b[39m# Plotting\u001b[39;00m\n\u001b[0;32m----> 4\u001b[0m plt\u001b[39m.\u001b[39mplot(lstm_model_history\u001b[39m.\u001b[39mhistory[\u001b[39m'\u001b[39m\u001b[39macc\u001b[39m\u001b[39m'\u001b[39m])\n\u001b[1;32m      5\u001b[0m plt\u001b[39m.\u001b[39mplot(lstm_model_history\u001b[39m.\u001b[39mhistory[\u001b[39m'\u001b[39m\u001b[39mval_acc\u001b[39m\u001b[39m'\u001b[39m])\n\u001b[1;32m      6\u001b[0m plt\u001b[39m.\u001b[39mtitle(\u001b[39m'\u001b[39m\u001b[39mModel Accuracy\u001b[39m\u001b[39m'\u001b[39m)\n",
      "\u001b[0;31mNameError\u001b[0m: name 'lstm_model_history' is not defined"
     ]
    }
   ],
   "source": [
    "import matplotlib.pyplot as plt\n",
    "\n",
    "# Plotting\n",
    "plt.plot(lstm_model_history.history['acc'])\n",
    "plt.plot(lstm_model_history.history['val_acc'])\n",
    "plt.title('Model Accuracy')\n",
    "plt.ylabel('Accuracy')\n",
    "plt.xlabel('Epoch')\n",
    "plt.legend(['Train', 'Validation'], loc='upper left')\n",
    "plt.show()\n",
    "\n",
    "plt.plot(lstm_model_history.history['loss'])\n",
    "plt.plot(lstm_model_history.history['val_loss'])\n",
    "plt.title('Model Loss')\n",
    "plt.ylabel('Loss')\n",
    "plt.xlabel('Epoch')\n",
    "plt.legend(['Train', 'Validation'], loc='upper left')\n",
    "plt.show()"
   ]
  }
 ],
 "metadata": {
  "kernelspec": {
   "display_name": "Python (tf_env)",
   "language": "python",
   "name": "tf_env"
  },
  "language_info": {
   "codemirror_mode": {
    "name": "ipython",
    "version": 3
   },
   "file_extension": ".py",
   "mimetype": "text/x-python",
   "name": "python",
   "nbconvert_exporter": "python",
   "pygments_lexer": "ipython3",
   "version": "3.8.19"
  },
  "orig_nbformat": 4
 },
 "nbformat": 4,
 "nbformat_minor": 2
}
